Workbook

Sheet original_file
A1: vaerk_id | B1: vrkanl_ny | C1: aar | D1: vaerk_navn | E1: vaerk_postnr | F1: vaerk_postdistrikt | G1: vaerk_kommune | H1: fv_net | I1: fv_net_navn | J1: selskab_id | K1: cvr | L1: selskab_navn | M1: kvoteaktivitet | N1: vrktypeid | O1: vrktypenavn | P1: anlaeg_navn | Q1: anlaegstype_navn | R1: DB07 | S1: NR117 | T1: aktoer | U1: idriftdato | V1: skrotdato | W1: indfyretkapacitet_MW | X1: elkapacitet_MW | Y1: varmekapacitet_MW | Z1: brutto_TJ | AA1: varmeprod_TJ | AB1: varmelev_TJ | AC1: elprod_TJ | AD1: ellev_TJ | AE1: andel_varmelev | AF1: andel_el | AG1: andel_process | AH1: kul_TJ | AI1: fuelolie_TJ | AJ1: spildolie_TJ | AK1: gasolie_TJ | AL1: raffinaderigas_TJ | AM1: lpg_TJ | AN1: naturgas_TJ | AO1: affald_TJ | AP1: biogas_TJ | AQ1: halm_TJ | AR1: skovflis_TJ | AS1: trae- og biomasseaffald_TJ | AT1: traepiller_TJ | AU1: bio-olie_TJ | AV1: braendselsfrit_TJ | AW1: solenergi_TJ | AX1: vandkraft_TJ | AY1: elektricitet_TJ | AZ1: omgivelsesvarme_TJ
A2: 1 | B2: 1-14 | C2: 2022 | D2: Crossbridge Energy A/S | E2: 7000 | F2: Fredericia | G2: 607 | H2: 81 | I2: TVIS | J2: 1 | K2: 10373816 | L2: Crossbridge Energy A/S | M2: 2 | N2: ER | O2: Erhvervsværk | P2: U-5800 Overskudsvarme (del af 1-2) | Q2: Overskudsvarme | R2: 192000 | S2: 190000 | T2: pvp | U2: 34335 | W2: 56 | X2: 0 | Y2: 56 | Z2: 1513.13 | AA2: 1513.13 | AB2: 1513.13 | AC2: 0 | AD2: 0 | AE2: 1 | AF2: 0 | AG2: 0 | AV2: 1513.13
A3: 1 | B3: 1-2 | C3: 2022 | D3: Crossbridge Energy A/S | E3: 7000 | F3: Fredericia | G3: 607 | H3: 81 | I3: TVIS | J3: 1 | K3: 10373816 | L3: Crossbridge Energy A/S | M3: 2 | N3: ER | O3: Erhvervsværk | P3: U-2000 Gasturbine | Q3: Gasturbine | R3: 192000 | S3: 190000 | T3: pev | U3: 33970 | W3: 97.23 | X3: 26 | Y3: 52 | Z3: 1883.0078 | AA3: 744.23 | AB3: 251.75 | AC3: 498.44009 | AD3: 498.44009 | AE3: 0.10695654 | AF3: 0.68381225 | AG3: 0.20923121 | AL3: 1883.0078
A4: 2 | B4: 2-8 | C4: 2022 | D4: Assens Fjernvarme Stejlebjergvej | E4: 5610 | F4: Assens | G4: 420 | H4: 71 | I4: Assens Fjernvarme | J4: 2362 | K4: 40517987 | L4: Assens Fjernvarme Produktion A/S | N4: DC | O4: Decentralt værk | P4: Varmepumpe | Q4: Varmepumpe Luft | R4: 353000 | S4: 350030 | T4: fvv | U4: 44343 | W4: 2.3 | X4: 0 | Y4: 7.2 | Z4: 27.4446 | AA4: 27.4446 | AB4: 27.4446 | AC4: 0 | AD4: 0 | AE4: 1 | AF4: 0 | AG4: 0 | AY4: 8.9960162 | AZ4: 18.448584
A5: 2 | B5: 2-1 | C5: 2022 | D5: Assens Fjernvarme Stejlebjergvej | E5: 5610 | F5: Assens | G5: 420 | H5: 71 | I5: Assens Fjernvarme | J5: 2362 | K5: 40517987 | L5: Assens Fjernvarme Produktion A/S | N5: DC | O5: Decentralt værk | P5: Blok I | Q5: Kedel | R5: 353000 | S5: 350030 | T5: fvv | U5: 30713 | W5: 20.8 | X5: 0 | Y5: 18.9 | Z5: 18.48307 | AA5: 17.577612 | AB5: 17.577612 | AC5: 0 | AD5: 0 | AE5: 1 | AF5: 0 | AG5: 0 | AT5: 18.48307
A6: 2 | B6: 2-4 | C6: 2022 | D6: Assens Fjernvarme Stejlebjergvej | E6: 5610 | F6: Assens | G6: 420 | H6: 71 | I6: Assens Fjernvarme | J6: 2362 | K6: 40517987 | L6: Assens Fjernvarme Produktion A/S | N6: DC | O6: Decentralt værk | P6: Blok II | Q6: Dampturbine | R6: 353000 | S6: 350030 | T6: kvt | U6: 36242 | W6: 17.2 | X6: 4.7 | Y6: 14.9 | Z6: 374.50837 | AA6: 275.28725 | AB6: 267.92435 | AC6: 68.56848 | AD6: 64.33956 | AE6: 0.5880504 | AF6: 0.4119496 | AG6: 0 | AK6: 0.17744 | AR6: 374.33093
A7: 3 | B7: 3-3 | C7: 2022 | D7: Assens Fjernvarme (Mariagerfjord) | E7: 9550 | F7: Mariager | G7: 846 | H7: 209 | I7: Assens (v. Mariager) Fjernvarme | J7: 4 | K7: 27837417 | L7: ASSENS FJERNVARME A M B A | N7: FJ | O7: Fjernvarmeværk | P7: Fliskedel | Q7: Kedel | R7: 353000 | S7: 350030 | T7: fvv | U7: 39722 | W7: 6 | X7: 0 | Y7: 6 | Z7: 73.7496 | AA7: 72.2736 | AB7: 72.2736 | AC7: 0 | AD7: 0 | AE7: 1 | AF7: 0 | AG7: 0 | AR7: 73.7496
A8: 3 | B8: 3-2 | C8: 2022 | D8: Assens Fjernvarme (Mariagerfjord) | E8: 9550 | F8: Mariager | G8: 846 | H8: 209 | I8: Assens (v. Mariager) Fjernvarme | J8: 4 | K8: 27837417 | L8: ASSENS FJERNVARME A M B A | N8: FJ | O8: Fjernvarmeværk | P8: Oliereservekedel | Q8: Kedel | R8: 353000 | S8: 350030 | T8: fvv | U8: 34639 | W8: 5.8 | X8: 0 | Y8: 5.8 | Z8: 0 | AA8: 0 | AB8: 0 | AC8: 0 | AD8: 0 | AE8: 1 | AF8: 0 | AG8: 0 | AK8: 0
A9: 4 | B9: 4-3 | C9: 2022 | D9: Aulum Fjernvarme A.m.b.a. (Rugbjergvej 3) | E9: 7490 | F9: Aulum | G9: 657 | H9: 159 | I9: Aulum Fjernvarme | J9: 5 | K9: 39042010 | L9: AULUM FJERNVARME AMBA | N9: FJ | O9: Fjernvarmeværk | P9: Kedel 2 6,6 MW, Naturgas | Q9: Kedel | R9: 353000 | S9: 350030 | T9: fvv | U9: 23986 | V9: 45291 | W9: 6.6 | X9: 0 | Y9: 5.9 | Z9: 0 | AA9: 0 | AB9: 0 | AC9: 0 | AD9: 0 | AE9: 1 | AF9: 0 | AG9: 0 | AN9: 0
A10: 4 | B10: 4-2 | C10: 2022 | D10: Aulum Fjernvarme A.m.b.a. (Rugbjergvej 3) | E10: 7490 | F10: Aulum | G10: 657 | H10: 159 | I10: Aulum Fjernvarme | J10: 5 | K10: 39042010 | L10: AULUM FJERNVARME AMBA | N10: FJ | O10: Fjernvarmeværk | P10: Kedel 1 4,1 MW, Gasolie | Q10: Kedel | R10: 353000 | S10: 350030 | T10: fvv | U10: 27973 | V10: 45291 | W10: 4.1 | X10: 0 | Y10: 3.28 | Z10: 0 | AA10: 0 | AB10: 0 | AC10: 0 | AD10: 0 | AE10: 1 | AF10: 0 | AG10: 0 | AK10: 0 | AM10: 0
A11: 5 | B11: 5-7 | C11: 2022 | D11: Aulum Fjernvarme A.m.b.a. (Kulvej 5) | E11: 7490 | F11: Aulum | G11: 657 | H11: 159 | I11: Aulum Fjernvarme | J11: 5 | K11: 39042010 | L11: AULUM FJERNVARME AMBA | M11: 1 | N11: DC | O11: Decentralt værk | P11: Varmepumpe 1 og 2 | Q11: Varmepumpe Luft | R11: 353000 | S11: 350030 | T11: fvv | U11: 44084 | W11: 1.2 | X11: 0 | Y11: 4 | Z11: 50.44068 | AA11: 50.44068 | AB11: 46.905624 | AC11: 0 | AD11: 0 | AE11: 1 | AF11: 0 | AG11: 0 | AY11: 16.259868 | AZ11: 34.180812
A12: 5 | B12: 5-2 | C12: 2022 | D12: Aulum Fjernvarme A.m.b.a. (Kulvej 5) | E12: 7490 | F12: Aulum | G12: 657 | H12: 159 | I12: Aulum Fjernvarme | J12: 5 | K12: 39042010 | L12: AULUM FJERNVARME AMBA | M12: 1 | N12: DC | O12: Decentralt værk | P12: Gasmotor | Q12: Forbrændingsmotor | R12: 353000 | S12: 350030 | T12: kvt | U12: 39063 | W12: 11.34 | X12: 5.1 | Y12: 5.65 | Z12: 17.865619 | AA12: 9.14616 | AB12: 9.14616 | AC12: 7.972812 | AD12: 7.902 | AE12: 0.40955356 | AF12: 0.59044644 | AG12: 0 | AN12: 17.865619
A13: 5 | B13: 5-3 | C13: 2022 | D13: Aulum Fjernvarme A.m.b.a. (Kulvej 5) | E13: 7490 | F13: Aulum | G13: 657 | H13: 159 | I13: Aulum Fjernvarme | J13: 5 | K13: 39042010 | L13: AULUM FJERNVARME AMBA | M13: 1 | N13: DC | O13: Decentralt værk | P13: Naturgas kedel | Q13: Kedel | R13: 353000 | S13: 350030 | T13: fvv | U13: 38749 | W13: 11 | X13: 0 | Y13: 11 | Z13: 2.9740392 | AA13: 3.05316 | AB13: 3.05316 | AC13: 0 | AD13: 0 | AE13: 1 | AF13: 0 | AG13: 0 | AN13: 2.9740392
A14: 5 | B14: 5-5 | C14: 2022 | D14: Aulum Fjernvarme A.m.b.a. (Kulvej 5) | E14: 7490 | F14: Aulum | G14: 657 | H14: 159 | I14: Aulum Fjernvarme | J14: 5 | K14: 39042010 | L14: AULUM FJERNVARME AMBA | M14: 1 | N14: DC | O14: Decentralt værk | P14: Elkedel (ikke kvoteomfattet) | Q14: Elpatron | R14: 353000 | S14: 350030 | T14: fvv | U14: 40452 | W14: 10 | X14: 0 | Y14: 10 | Z14: 21.703788 | AA14: 21.51864 | AB14: 21.51864 | AC14: 0 | AD14: 0 | AE14: 1 | AF14: 0 | AG14: 0 | AY14: 21.703788
A15: 5 | B15: 5-6 | C15: 2022 | D15: Aulum Fjernvarme A.m.b.a. (Kulvej 5) | E15: 7490 | F15: Aulum | G15: 657 | H15: 159 | I15: Aulum Fjernvarme | J15: 5 | K15: 39042010 | L15: AULUM FJERNVARME AMBA | M15: 1 | N15: DC | O15: Decentralt værk | P15: Solvarme | Q15: Solvarme | R15: 353000 | S15: 350030 | T15: fvv | U15: 42248 | W15: 11.1 | X15: 0 | Y15: 11.1 | Z15: 28.5372 | AA15: 28.5372 | AB15: 27.3996 | AC15: 0 | AD15: 0 | AE15: 1 | AF15: 0 | AG15: 0 | AW15: 28.5372
A16: 6 | B16: 6-10 | C16: 2022 | D16: Aabybro Fjernvarmeværk | E16: 9440 | F16: Aabybro | G16: 849 | H16: 329 | I16: Aabybro Fjernvarme | J16: 6 | K16: 17779710 | L16: Aabybro-Jetsmark Fjernvarme A.m.b.a. | N16: FJ | O16: Fjernvarmeværk | P16: Biomasse kedel | Q16: Kedel | R16: 353000 | S16: 350030 | T16: fvv | U16: 42474 | W16: 10 | X16: 0 | Y16: 10 | Z16: 149.957 | AA16: 158.2956 | AB16: 158.2956 | AC16: 0 | AD16: 0 | AE16: 1 | AF16: 0 | AG16: 0 | AR16: 149.957
A17: 6 | B17: 6-8 | C17: 2022 | D17: Aabybro Fjernvarmeværk | E17: 9440 | F17: Aabybro | G17: 849 | H17: 329 | I17: Aabybro Fjernvarme | J17: 6 | K17: 17779710 | L17: Aabybro-Jetsmark Fjernvarme A.m.b.a. | N17: FJ | O17: Fjernvarmeværk | P17: Gaskedel 3 | Q17: Kedel | R17: 353000 | S17: 350030 | T17: fvv | U17: 31413 | W17: 4 | X17: 0 | Y17: 4 | Z17: 0 | AA17: 0 | AB17: 0 | AC17: 0 | AD17: 0 | AE17: 1 | AF17: 0 | AG17: 0 | AN17: 0
A18: 6 | B18: 6-11 | C18: 2022 | D18: Aabybro Fjernvarmeværk | E18: 9440 | F18: Aabybro | G18: 849 | H18: 329 | I18: Aabybro Fjernvarme | J18: 6 | K18: 17779710 | L18: Aabybro-Jetsmark Fjernvarme A.m.b.a. | N18: FJ | O18: Fjernvarmeværk | P18: Solvarme | Q18: Solvarme | R18: 353000 | S18: 350030 | T18: fvv | U18: 43358 | W18: 17 | X18: 0 | Y18: 17 | Z18: 54.0612 | AA18: 54.0612 | AB18: 54.0612 | AC18: 0 | AD18: 0 | AE18: 1 | AF18: 0 | AG18: 0 | AW18: 54.0612
A19: 6 | B19: 6-9 | C19: 2022 | D19: Aabybro Fjernvarmeværk | E19: 9440 | F19: Aabybro | G19: 849 | H19: 329 | I19: Aabybro Fjernvarme | J19: 6 | K19: 17779710 | L19: Aabybro-Jetsmark Fjernvarme A.m.b.a. | N19: FJ | O19: Fjernvarmeværk | P19: Gaskedel 4 | Q19: Kedel | R19: 353000 | S19: 350030 | T19: fvv | U19: 31413 | W19: 4 | X19: 0 | Y19: 4 | Z19: 0 | AA19: 0 | AB19: 0 | AC19: 0 | AD19: 0 | AE19: 1 | AF19: 0 | AG19: 0 | AN19: 0
A20: 7 | B20: 7-16 | C20: 2022 | D20: Aalborg Portland A/S | E20: 9220 | F20: Aalborg Øst | G20: 851 | H20: 295 | I20: Aalborg Fjernvarme | J20: 2258 | K20: 36428112 | L20: Aalborg Portland A/S | M20: 10 | N20: ER | O20: Erhvervsværk | P20: Varmegenvindingsanlæg for ovn 73,74,78,79 | Q20: Overskudsvarme | R20: 235100 | S20: 230020 | T20: pvp | U20: 33554 | W20: 182 | X20: 0 | Y20: 70 | Z20: 884.01252 | AA20: 844.054 | AB20: 820.203 | AC20: 0 | AD20: 0 | AE20: 0.97174233 | AF20: 0 | AG20: 0.028257671 | AV20: 844.054 | AY20: 39.958524
A21: 7 | B21: 7-17 | C21: 2022 | D21: Aalborg Portland A/S | E21: 9220 | F21: Aalborg Øst | G21: 851 | H21: 295 | I21: Aalborg Fjernvarme | J21: 2258 | K21: 36428112 | L21: Aalborg Portland A/S | M21: 10 | N21: ER | O21: Erhvervsværk | P21: Varmegevindingsanlæg for ovn 76 | Q21: Overskudsvarme | R21: 235100 | S21: 230020 | T21: pvp | U21: 37945 | W21: 80 | X21: 0 | Y21: 32 | Z21: 469.6801 | AA21: 462.917 | AB21: 462.917 | AC21: 0 | AD21: 0 | AE21: 1 | AF21: 0 | AG21: 0 | AV21: 462.917 | AY21: 6.7630968
A22: 8 | B22: 8-2 | C22: 2022 | D22: Nordværk I/S, Energianlæg Hjørring | E22: 9800 | F22: Hjørring | G22: 860 | H22: 298 | I22: Hjørring Fjernvarme (inkl. Hirtshals Fjernvarme fra 2011) | J22: 1378 | K22: 46076753 | L22: Nordværk I/S | M22: 1 | N22: ER | O22: Erhvervsværk | P22: Ovnlinje 3 | Q22: Dampturbine | R22: 382120 | S22: 383900 | T22: pev | U22: 35886 | W22: 20.5 | X22: 4.6 | Y22: 16.8 | Z22: 690.75712 | AA22: 545.68879 | AB22: 532.1961 | AC22: 130.41936 | AD22: 105.53112 | AE22: 0.61636264 | AF22: 0.36801081 | AG22: 0.015626554 | AJ22: 0.200282 | AK22: 0.6836822 | AO22: 642.69867 | AS22: 47.17449
A23: 8 | B23: 8-1 | C23: 2022 | D23: Nordværk I/S, Energianlæg Hjørring | E23: 9800 | F23: Hjørring | G23: 860 | H23: 298 | I23: Hjørring Fjernvarme (inkl. Hirtshals Fjernvarme fra 2011) | J23: 1378 | K23: 46076753 | L23: Nordværk I/S | M23: 1 | N23: ER | O23: Erhvervsværk | P23: Ovnlinje 2 | Q23: Kedel | R23: 382120 | S23: 383900 | T23: pvp | U23: 31413 | W23: 11.1 | X23: 0 | Y23: 18.5 | Z23: 292.96679 | AA23: 312.62954 | AB23: 304.89948 | AC23: 0 | AD23: 0 | AE23: 0.97527405 | AF23: 0 | AG23: 0.024725955 | AJ23: 0.051118 | AK23: 0.2826556 | AO23: 272.37834 | AS23: 20.254679
A24: 9 | B24: 9-3 | C24: 2022 | D24: Agersted Varmeværk | E24: 9330 | F24: Dronninglund | G24: 810 | H24: 280 | I24: Agersted Fjernvarme | J24: 9 | K24: 19774015 | L24: AGERSTED VARMEVÆRK | N24: DC | O24: Decentralt værk | P24: Kedelanlæg | Q24: Kedel | R24: 353000 | S24: 350030 | T24: fvv | U24: 32143 | W24: 1.7 | X24: 0 | Y24: 1.86 | Z24: 1.9822572 | AA24: 1.98216 | AB24: 1.98216 | AC24: 0 | AD24: 0 | AE24: 1 | AF24: 0 | AG24: 0 | AN24: 1.9822572
A25: 9 | B25: 9-5 | C25: 2022 | D25: Agersted Varmeværk | E25: 9330 | F25: Dronninglund | G25: 810 | H25: 280 | I25: Agersted Fjernvarme | J25: 9 | K25: 19774015 | L25: AGERSTED VARMEVÆRK | N25: DC | O25: Decentralt værk | P25: Motor 1 | Q25: Forbrændingsmotor | R25: 353000 | S25: 350030 | T25: kvt | U25: 38615 | W25: 3.3 | X25: 1.41 | Y25: 1.9 | Z25: 2.0181348 | AA25: 1.01628 | AB25: 1.01628 | AC25: 0.72972 | AD25: 0.72972 | AE25: 0.40285912 | AF25: 0.59714088 | AG25: 0 | AN25: 2.0181348
A26: 10 | B26: 10-4 | C26: 2022 | D26: Albertslund Varmeværk | E26: 2620 | F26: Albertslund | G26: 165 | H26: 2 | I26: Storkøbenhavns Fjernvarme | J26: 10 | K26: 66137112 | L26: Albertslund Kommune | M26: 1 | N26: FJ | O26: Fjernvarmeværk | P26: Kedel 5 Falk.b. | Q26: Kedel | R26: 353000 | S26: 350030 | T26: fvv | U26: 24108 | W26: 10.1 | X26: 0 | Y26: 9.3 | Z26: 0.011088 | AA26: 0.01038 | AB26: 0.01038 | AC26: 0 | AD26: 0 | AE26: 1 | AF26: 0 | AG26: 0 | AN26: 0.011088
A27: 10 | B27: 10-5 | C27: 2022 | D27: Albertslund Varmeværk | E27: 2620 | F27: Albertslund | G27: 165 | H27: 2 | I27: Storkøbenhavns Fjernvarme | J27: 10 | K27: 66137112 | L27: Albertslund Kommune | M27: 1 | N27: FJ | O27: Fjernvarmeværk | P27: Kedel 6 Parca | Q27: Kedel | R27: 353000 | S27: 350030 | T27: fvv | U27: 24838 | W27: 24.754 | X27: 0 | Y27: 21.888 | Z27: 5.075605 | AA27: 4.022 | AB27: 4.022 | AC27: 0 | AD27: 0 | AE27: 1 | AF27: 0 | AG27: 0 | AK27: 5.075605
A28: 10 | B28: 10-2 | C28: 2022 | D28: Albertslund Varmeværk | E28: 2620 | F28: Albertslund | G28: 165 | H28: 2 | I28: Storkøbenhavns Fjernvarme | J28: 10 | K28: 66137112 | L28: Albertslund Kommune | M28: 1 | N28: FJ | O28: Fjernvarmeværk | P28: Kedel 3 Parca | Q28: Kedel | R28: 353000 | S28: 350030 | T28: fvv | U28: 25934 | W28: 25.3 | X28: 0 | Y28: 23.3 | Z28: 6.772256 | AA28: 6.013 | AB28: 6.013 | AC28: 0 | AD28: 0 | AE28: 1 | AF28: 0 | AG28: 0 | AK28: 6.772256
A29: 10 | B29: 10-10 | C29: 2022 | D29: Albertslund Varmeværk | E29: 2620 | F29: Albertslund | G29: 165 | H29: 2 | I29: Storkøbenhavns Fjernvarme | J29: 10 | K29: 66137112 | L29: Albertslund Kommune | M29: 1 | N29: FJ | O29: Fjernvarmeværk | P29: Kedel 9 | Q29: Kedel | R29: 353000 | S29: 350030 | T29: fvv | U29: 27030 | W29: 24.405 | X29: 0 | Y29: 22.252 | Z29: 0 | AA29: 0 | AB29: 0 | AC29: 0 | AD29: 0 | AE29: 1 | AF29: 0 | AG29: 0 | AK29: 0 | AM29: 0
A30: 10 | B30: 10-6 | C30: 2022 | D30: Albertslund Varmeværk | E30: 2620 | F30: Albertslund | G30: 165 | H30: 2 | I30: Storkøbenhavns Fjernvarme | J30: 10 | K30: 66137112 | L30: Albertslund Kommune | M30: 1 | N30: FJ | O30: Fjernvarmeværk | P30: Kedel 7A | Q30: Kedel | R30: 353000 | S30: 350030 | T30: fvv | U30: 30317 | W30: 12.6 | X30: 0 | Y30: 11.6 | Z30: 0.9964152 | AA30: 0.756 | AB30: 0.756 | AC30: 0 | AD30: 0 | AE30: 1 | AF30: 0 | AG30: 0 | AN30: 0.9964152
A31: 10 | B31: 10-9 | C31: 2022 | D31: Albertslund Varmeværk | E31: 2620 | F31: Albertslund | G31: 165 | H31: 2 | I31: Storkøbenhavns Fjernvarme | J31: 10 | K31: 66137112 | L31: Albertslund Kommune | M31: 1 | N31: FJ | O31: Fjernvarmeværk | P31: Kedel 8B | Q31: Kedel | R31: 353000 | S31: 350030 | T31: fvv | U31: 30317 | W31: 12.6 | X31: 0 | Y31: 11.6 | Z31: 6.1495078 | AA31: 5.78339 | AB31: 5.78339 | AC31: 0 | AD31: 0 | AE31: 1 | AF31: 0 | AG31: 0 | AK31: 6.130183 | AN31: 0.0193248
A32: 10 | B32: 10-8 | C32: 2022 | D32: Albertslund Varmeværk | E32: 2620 | F32: Albertslund | G32: 165 | H32: 2 | I32: Storkøbenhavns Fjernvarme | J32: 10 | K32: 66137112 | L32: Albertslund Kommune | M32: 1 | N32: FJ | O32: Fjernvarmeværk | P32: Kedel 8A | Q32: Kedel | R32: 353000 | S32: 350030 | T32: fvv | U32: 30317 | W32: 12.6 | X32: 0 | Y32: 11.6 | Z32: 3.7388144 | AA32: 3.185 | AB32: 3.185 | AC32: 0 | AD32: 0 | AE32: 1 | AF32: 0 | AG32: 0 | AK32: 2.596988 | AN32: 1.1418264
A33: 10 | B33: 10-7 | C33: 2022 | D33: Albertslund Varmeværk | E33: 2620 | F33: Albertslund | G33: 165 | H33: 2 | I33: Storkøbenhavns Fjernvarme | J33: 10 | K33: 66137112 | L33: Albertslund Kommune | M33: 1 | N33: FJ | O33: Fjernvarmeværk | P33: Kedel 7B | Q33: Kedel | R33: 353000 | S33: 350030 | T33: fvv | U33: 30317 | W33: 12.6 | X33: 0 | Y33: 11.6 | Z33: 13.111041 | AA33: 11.746 | AB33: 11.746 | AC33: 0 | AD33: 0 | AE33: 1 | AF33: 0 | AG33: 0 | AK33: 13.067441 | AN33: 0.0435996
A34: 10 | B34: 10-3 | C34: 2022 | D34: Albertslund Varmeværk | E34: 2620 | F34: Albertslund | G34: 165 | H34: 2 | I34: Storkøbenhavns Fjernvarme | J34: 10 | K34: 66137112 | L34: Albertslund Kommune | M34: 1 | N34: FJ | O34: Fjernvarmeværk | P34: Kedel 4 Falk.b. | Q34: Kedel | R34: 353000 | S34: 350030 | T34: fvv | U34: 24108 | W34: 10.1 | X34: 0 | Y34: 9.3 | Z34: 0.0203544 | AA34: 0.01802 | AB34: 0.01802 | AC34: 0 | AD34: 0 | AE34: 1 | AF34: 0 | AG34: 0 | AN34: 0.0203544
A35: 11 | B35: 11-4 | C35: 2022 | D35: Allingåbro Varmeværk | E35: 8961 | F35: Allingåbro | G35: 707 | H35: 219 | I35: Allingåbro Fjernvarme | J35: 11 | K35: 18027410 | L35: ALLINGÅBRO VARMEVÆRK A M B A | N35: FJ | O35: Fjernvarmeværk | P35: Flis-kedel | Q35: Kedel | R35: 353000 | S35: 350030 | T35: fvv | U35: 37530 | W35: 4.985 | X35: 0 | Y35: 6 | Z35: 54.993411 | AA35: 58.692852 | AB35: 58.692852 | AC35: 0 | AD35: 0 | AE35: 1 | AF35: 0 | AG35: 0 | AR35: 54.993411
A36: 11 | B36: 11-3 | C36: 2022 | D36: Allingåbro Varmeværk | E36: 8961 | F36: Allingåbro | G36: 707 | H36: 219 | I36: Allingåbro Fjernvarme | J36: 11 | K36: 18027410 | L36: ALLINGÅBRO VARMEVÆRK A M B A | N36: FJ | O36: Fjernvarmeværk | P36: Oliekedel (ny) | Q36: Kedel | R36: 353000 | S36: 350030 | T36: fvv | U36: 39264 | V36: 45684 | W36: 5.5 | X36: 0 | Y36: 5.5 | Z36: 1.087142 | AA36: 1.095948 | AB36: 1.095948 | AC36: 0 | AD36: 0 | AE36: 1 | AF36: 0 | AG36: 0 | AK36: 1.087142
A37: 12 | B37: 12-1 | C37: 2022 | D37: Als Fjernvarme, Rørsangervej 3 | E37: 9560 | F37: Hadsund | G37: 846 | H37: 292 | I37: Als Fjernvarme | J37: 12 | K37: 11304028 | L37: ALS FJERNVARME AMBA | N37: FJ | O37: Fjernvarmeværk | P37: Oliecentral | Q37: Kedel | R37: 353000 | S37: 350030 | T37: fvv | U37: 23743 | W37: 5.5 | X37: 0 | Y37: 5.5 | Z37: 0 | AA37: 0 | AB37: 0 | AC37: 0 | AD37: 0 | AE37: 1 | AF37: 0 | AG37: 0 | AK37: 0
A38: 13 | B38: 13-2 | C38: 2022 | D38: Als Fjernvarme, Rørsangervej 26 | E38: 9560 | F38: Hadsund | G38: 846 | H38: 292 | I38: Als Fjernvarme | J38: 12 | K38: 11304028 | L38: ALS FJERNVARME AMBA | N38: FJ | O38: Fjernvarmeværk | P38: Solvarme 6000m2 | Q38: Solvarme | R38: 353000 | S38: 350030 | T38: fvv | U38: 42461 | W38: 4 | X38: 0 | Y38: 4 | Z38: 10.872 | AA38: 10.872 | AB38: 10.872 | AC38: 0 | AD38: 0 | AE38: 1 | AF38: 0 | AG38: 0 | AW38: 10.872
A39: 13 | B39: 13-1 | C39: 2022 | D39: Als Fjernvarme, Rørsangervej 26 | E39: 9560 | F39: Hadsund | G39: 846 | H39: 292 | I39: Als Fjernvarme | J39: 12 | K39: 11304028 | L39: ALS FJERNVARME AMBA | N39: FJ | O39: Fjernvarmeværk | P39: Halm central | Q39: Kedel | R39: 353000 | S39: 350030 | T39: fvv | U39: 37895 | W39: 3.5 | X39: 0 | Y39: 3.15 | Z39: 48.7925 | AA39: 46.4292 | AB39: 46.4292 | AC39: 0 | AD39: 0 | AE39: 1 | AF39: 0 | AG39: 0 | AQ39: 25.5925 | AS39: 23.2
A40: 15 | B40: 15-5 | C40: 2022 | D40: Flauenskjold Varmeværk A.m.b.a | E40: 9330 | F40: Dronninglund | G40: 810 | H40: 283 | I40: Flauenskjold Fjernvarme | J40: 14 | K40: 20023317 | L40: Flauenskjold Varmeværk A.m.b.a | N40: DC | O40: Decentralt værk | P40: varmepumpe | Q40: Varmepumpe Luft | R40: 353000 | S40: 350030 | T40: fvv | U40: 44866 | W40: 0.5 | X40: 0 | Y40: 1.6 | Z40: 2.8332 | AA40: 2.8332 | AB40: 2.8332 | AC40: 0 | AD40: 0 | AE40: 1 | AF40: 0 | AG40: 0 | AY40: 1.0044 | AZ40: 1.8288
...

Sheet DA-EN translation help
A2: anlægstype | B2: unit type
A3: Gasturbine | B3: gas turbine
A4: Overskudsvarme | B4: surplus heat
A5: Kedel | B5: hot water boiler
A6: Elpatron | B6: electric boiler
A7: Forbrændingsmotor | B7: internal combustion engine
A8: Nødstrømsanlæg | B8: emergency power plant
A9: Solvarme | B9: solar heating panels
A10: Dampturbine | B10: steam turbine
A11: Anden | B11: others
A12: Dampkedel | B12: steam boiler
A13: Varmepumpe | B13: heat pump
... A37: Vandkraft | B37: hydro power

Sheet filtered_classified
A1: vaerk_id | B1: vrkanl_ny | C1: aar | D1: vaerk_navn | E1: vaerk_postnr | F1: vaerk_postdistrikt | G1: vaerk_kommune | H1: fv_net | I1: fv_net_navn | J1: selskab_id | K1: cvr | L1: selskab_navn | M1: kvoteaktivitet | N1: vrktypeid | O1: vrktypenavn | P1: anlaeg_navn | Q1: anlaegstype_navn | R1: DB07 | S1: NR117 | T1: aktoer | U1: idriftdato | V1: skrotdato | W1: CATEGORY | X1: TECHTYPE | Y1: ETS | Z1: MAIN_FUEL | AA1: STATUS | AB1: MODEL_NAME | AC1: COMMENT | AD1: indfyretkapacitet_MW | AE1: elkapacitet_MW | AF1: varmekapacitet_MW | AG1: brutto_TJ | AH1: varmeprod_TJ | AI1: varmelev_TJ | AJ1: elprod_TJ | AK1: ellev_TJ | AL1: andel_varmelev | AM1: andel_el | AN1: andel_process | AO1: kul_TJ | AP1: fuelolie_TJ | AQ1: spildolie_TJ | AR1: gasolie_TJ | AS1: raffinaderigas_TJ | AT1: lpg_TJ | AU1: naturgas_TJ | AV1: affald_TJ | AW1: biogas_TJ | AX1: halm_TJ | AY1: skovflis_TJ | AZ1: trae- og biomasseaffald_TJ | BA1: traepiller_TJ | BB1: bio-olie_TJ | BC1: braendselsfrit_TJ | BD1: solenergi_TJ | BE1: vandkraft_TJ | BF1: elektricitet_TJ | BG1: omgivelsesvarme_TJ | BH1: coal (share) | BI1: fuel-oil (share) | BJ1: waste-oil (share) | BK1: gas-oil (share) | BL1: refinery gas (share) | BM1: LPG (share} | BN1: natural gas (share) | BO1: municipal waste (share) | BP1: biogas (share) | BQ1: straw (share) | BR1: wood chips (share) | BS1: wood waste (share) | BT1: wood pellets (share) | BU1: bio-oil (share) | BV1: fuel-free (share) | BW1: solar (share) | BX1: hydropower (share) | BY1: electricity (share) | BZ1: ambient heat (share) (ambient heat)
A2: 10 | B2: 10-4 | C2: 2023 | D2: Albertslund Varmeværk | E2: 2620 | F2: Albertslund | G2: 165 | H2: 2 | I2: Storkøbenhavns Fjernvarme | J2: 10 | K2: 66137112 | L2: Albertslund Kommune | M2: 1 | N2: FJ | O2: Fjernvarmeværk | P2: Kedel 5 Falk.b. | Q2: Kedel | R2: 353000 | S2: 350030 | T2: fvv | U2: 24108 | W2: HO | X2: BOILER | Y2: YES | Z2: NATURAL GAS | AA2: ACTIVE | AB2: HOB_NG | AD2: 10.1 | AE2: 0 | AF2: 9.3 | AG2: 2.1508419 | AH2: 1.463 | AI2: 1.463 | AJ2: 0 | AK2: 0 | AL2: 1 | AM2: 0 | AN2: 0 | AU2: 2.1508419 | BH2: =IFERROR(AO2/SUM($AO2:$BG2),"-") -> 0 | BI2: =IFERROR(AP2/SUM($AO2:$BG2),"-") -> 0 | BJ2: =IFERROR(AQ2/SUM($AO2:$BG2),"-") -> 0 | BK2: =IFERROR(AR2/SUM($AO2:$BG2),"-") -> 0 | BL2: =IFERROR(AS2/SUM($AO2:$BG2),"-") -> 0 | BM2: =IFERROR(AT2/SUM($AO2:$BG2),"-") -> 0 | BN2: =IFERROR(AU2/SUM($AO2:$BG2),"-") -> 1 | BO2: =IFERROR(AV2/SUM($AO2:$BG2),"-") -> 0 | ... BZ2: =IFERROR(BG2/SUM($AO2:$BG2),"-") -> 0
A3: 10 | B3: 10-5 | C3: 2023 | D3: Albertslund Varmeværk | E3: 2620 | F3: Albertslund | G3: 165 | H3: 2 | I3: Storkøbenhavns Fjernvarme | J3: 10 | K3: 66137112 | L3: Albertslund Kommune | M3: 1 | N3: FJ | O3: Fjernvarmeværk | P3: Kedel 6 Parca | Q3: Kedel | R3: 353000 | S3: 350030 | T3: fvv | U3: 24838 | W3: HO | X3: BOILER | Y3: YES | Z3: GAS OIL | AA3: ACTIVE | AB3: HOB_GO | AD3: 24.754 | AE3: 0 | AF3: 21.888 | AG3: 0.530876 | AH3: 0.446 | AI3: 0.446 | AJ3: 0 | AK3: 0 | AL3: 1 | AM3: 0 | AN3: 0 | AR3: 0.530876 | BH3: =IFERROR(AO3/SUM($AO3:$BG3),"-") -> 0 | BI3: =IFERROR(AP3/SUM($AO3:$BG3),"-") -> 0 | BJ3: =IFERROR(AQ3/SUM($AO3:$BG3),"-") -> 0 | BK3: =IFERROR(AR3/SUM($AO3:$BG3),"-") -> 1 | BL3: =IFERROR(AS3/SUM($AO3:$BG3),"-") -> 0 | BM3: =IFERROR(AT3/SUM($AO3:$BG3),"-") -> 0 | BN3: =IFERROR(AU3/SUM($AO3:$BG3),"-") -> 0 | BO3: =IFERROR(AV3/SUM($AO3:$BG3),"-") -> 0 | ... BZ3: =IFERROR(BG3/SUM($AO3:$BG3),"-") -> 0
A4: 10 | B4: 10-2 | C4: 2023 | D4: Albertslund Varmeværk | E4: 2620 | F4: Albertslund | G4: 165 | H4: 2 | I4: Storkøbenhavns Fjernvarme | J4: 10 | K4: 66137112 | L4: Albertslund Kommune | M4: 1 | N4: FJ | O4: Fjernvarmeværk | P4: Kedel 3 Parca | Q4: Kedel | R4: 353000 | S4: 350030 | T4: fvv | U4: 25934 | W4: HO | X4: BOILER | Y4: YES | Z4: GAS OIL | AA4: ACTIVE | AB4: HOB_GO | AD4: 25.3 | AE4: 0 | AF4: 23.3 | AG4: 0.100436 | AH4: 0.088 | AI4: 0.088 | AJ4: 0 | AK4: 0 | AL4: 1 | AM4: 0 | AN4: 0 | AR4: 0.100436 | BH4: =IFERROR(AO4/SUM($AO4:$BG4),"-") -> 0 | BI4: =IFERROR(AP4/SUM($AO4:$BG4),"-") -> 0 | BJ4: =IFERROR(AQ4/SUM($AO4:$BG4),"-") -> 0 | BK4: =IFERROR(AR4/SUM($AO4:$BG4),"-") -> 1 | BL4: =IFERROR(AS4/SUM($AO4:$BG4),"-") -> 0 | BM4: =IFERROR(AT4/SUM($AO4:$BG4),"-") -> 0 | BN4: =IFERROR(AU4/SUM($AO4:$BG4),"-") -> 0 | BO4: =IFERROR(AV4/SUM($AO4:$BG4),"-") -> 0 | ... BZ4: =IFERROR(BG4/SUM($AO4:$BG4),"-") -> 0
A5: 10 | B5: 10-3 | C5: 2023 | D5: Albertslund Varmeværk | E5: 2620 | F5: Albertslund | G5: 165 | H5: 2 | I5: Storkøbenhavns Fjernvarme | J5: 10 | K5: 66137112 | L5: Albertslund Kommune | M5: 1 | N5: FJ | O5: Fjernvarmeværk | P5: Kedel 4 Falk.b. | Q5: Kedel | R5: 353000 | S5: 350030 | T5: fvv | U5: 24108 | W5: HO | X5: BOILER | Y5: YES | Z5: NATURAL GAS | AA5: ACTIVE | AB5: HOB_NG | AD5: 10.1 | AE5: 0 | AF5: 9.3 | AG5: 1.7896468 | AH5: 1.203 | AI5: 1.203 | AJ5: 0 | AK5: 0 | AL5: 1 | AM5: 0 | AN5: 0 | AU5: 1.7896468 | BH5: =IFERROR(AO5/SUM($AO5:$BG5),"-") -> 0 | BI5: =IFERROR(AP5/SUM($AO5:$BG5),"-") -> 0 | BJ5: =IFERROR(AQ5/SUM($AO5:$BG5),"-") -> 0 | BK5: =IFERROR(AR5/SUM($AO5:$BG5),"-") -> 0 | BL5: =IFERROR(AS5/SUM($AO5:$BG5),"-") -> 0 | BM5: =IFERROR(AT5/SUM($AO5:$BG5),"-") -> 0 | BN5: =IFERROR(AU5/SUM($AO5:$BG5),"-") -> 1 | BO5: =IFERROR(AV5/SUM($AO5:$BG5),"-") -> 0 | ... BZ5: =IFERROR(BG5/SUM($AO5:$BG5),"-") -> 0
A6: 10 | B6: 10-8 | C6: 2023 | D6: Albertslund Varmeværk | E6: 2620 | F6: Albertslund | G6: 165 | H6: 2 | I6: Storkøbenhavns Fjernvarme | J6: 10 | K6: 66137112 | L6: Albertslund Kommune | M6: 1 | N6: FJ | O6: Fjernvarmeværk | P6: Kedel 8A | Q6: Kedel | R6: 353000 | S6: 350030 | T6: fvv | U6: 30317 | W6: HO | X6: BOILER | Y6: YES | Z6: NATURAL GAS | AA6: ACTIVE | AB6: HOB_NG | AD6: 12.6 | AE6: 0 | AF6: 11.6 | AG6: 14.226712 | AH6: 10.706 | AI6: 10.706 | AJ6: 0 | AK6: 0 | AL6: 1 | AM6: 0 | AN6: 0 | AU6: 14.226712 | BH6: =IFERROR(AO6/SUM($AO6:$BG6),"-") -> 0 | BI6: =IFERROR(AP6/SUM($AO6:$BG6),"-") -> 0 | BJ6: =IFERROR(AQ6/SUM($AO6:$BG6),"-") -> 0 | BK6: =IFERROR(AR6/SUM($AO6:$BG6),"-") -> 0 | BL6: =IFERROR(AS6/SUM($AO6:$BG6),"-") -> 0 | BM6: =IFERROR(AT6/SUM($AO6:$BG6),"-") -> 0 | BN6: =IFERROR(AU6/SUM($AO6:$BG6),"-") -> 1 | BO6: =IFERROR(AV6/SUM($AO6:$BG6),"-") -> 0 | ... BZ6: =IFERROR(BG6/SUM($AO6:$BG6),"-") -> 0
A7: 10 | B7: 10-7 | C7: 2023 | D7: Albertslund Varmeværk | E7: 2620 | F7: Albertslund | G7: 165 | H7: 2 | I7: Storkøbenhavns Fjernvarme | J7: 10 | K7: 66137112 | L7: Albertslund Kommune | M7: 1 | N7: FJ | O7: Fjernvarmeværk | P7: Kedel 7B | Q7: Kedel | R7: 353000 | S7: 350030 | T7: fvv | U7: 30317 | W7: HO | X7: BOILER | Y7: YES | Z7: NATURAL GAS | AA7: ACTIVE | AB7: HOB_NG | AD7: 12.6 | AE7: 0 | AF7: 11.6 | AG7: 8.7013987 | AH7: 6.633 | AI7: 6.633 | AJ7: 0 | AK7: 0 | AL7: 1 | AM7: 0 | AN7: 0 | AR7: 0.132719 | AU7: 8.5686797 | BH7: =IFERROR(AO7/SUM($AO7:$BG7),"-") -> 0 | BI7: =IFERROR(AP7/SUM($AO7:$BG7),"-") -> 0 | BJ7: =IFERROR(AQ7/SUM($AO7:$BG7),"-") -> 0 | BK7: =IFERROR(AR7/SUM($AO7:$BG7),"-") -> 0.015252605 | BL7: =IFERROR(AS7/SUM($AO7:$BG7),"-") -> 0 | BM7: =IFERROR(AT7/SUM($AO7:$BG7),"-") -> 0 | BN7: =IFERROR(AU7/SUM($AO7:$BG7),"-") -> 0.98474739 | BO7: =IFERROR(AV7/SUM($AO7:$BG7),"-") -> 0 | ... BZ7: =IFERROR(BG7/SUM($AO7:$BG7),"-") -> 0
A8: 10 | B8: 10-10 | C8: 2023 | D8: Albertslund Varmeværk | E8: 2620 | F8: Albertslund | G8: 165 | H8: 2 | I8: Storkøbenhavns Fjernvarme | J8: 10 | K8: 66137112 | L8: Albertslund Kommune | M8: 1 | N8: FJ | O8: Fjernvarmeværk | P8: Kedel 9 | Q8: Kedel | R8: 353000 | S8: 350030 | T8: fvv | U8: 27030 | W8: HO | X8: BOILER | Y8: YES | Z8: GAS OIL | AA8: ACTIVE | AB8: HOB_GO | AD8: 24.405 | AE8: 0 | AF8: 22.252 | AG8: 0.660008 | AH8: 0.593 | AI8: 0.593 | AJ8: 0 | AK8: 0 | AL8: 1 | AM8: 0 | AN8: 0 | AR8: 0.660008 | BH8: =IFERROR(AO8/SUM($AO8:$BG8),"-") -> 0 | BI8: =IFERROR(AP8/SUM($AO8:$BG8),"-") -> 0 | BJ8: =IFERROR(AQ8/SUM($AO8:$BG8),"-") -> 0 | BK8: =IFERROR(AR8/SUM($AO8:$BG8),"-") -> 1 | BL8: =IFERROR(AS8/SUM($AO8:$BG8),"-") -> 0 | BM8: =IFERROR(AT8/SUM($AO8:$BG8),"-") -> 0 | BN8: =IFERROR(AU8/SUM($AO8:$BG8),"-") -> 0 | BO8: =IFERROR(AV8/SUM($AO8:$BG8),"-") -> 0 | ... BZ8: =IFERROR(BG8/SUM($AO8:$BG8),"-") -> 0
A9: 10 | B9: 10-6 | C9: 2023 | D9: Albertslund Varmeværk | E9: 2620 | F9: Albertslund | G9: 165 | H9: 2 | I9: Storkøbenhavns Fjernvarme | J9: 10 | K9: 66137112 | L9: Albertslund Kommune | M9: 1 | N9: FJ | O9: Fjernvarmeværk | P9: Kedel 7A | Q9: Kedel | R9: 353000 | S9: 350030 | T9: fvv | U9: 30317 | W9: HO | X9: BOILER | Y9: YES | Z9: NATURAL GAS | AA9: ACTIVE | AB9: HOB_NG | AD9: 12.6 | AE9: 0 | AF9: 11.6 | AG9: 7.8859242 | AH9: 5.367 | AI9: 5.367 | AJ9: 0 | AK9: 0 | AL9: 1 | AM9: 0 | AN9: 0 | AU9: 7.8859242 | BH9: =IFERROR(AO9/SUM($AO9:$BG9),"-") -> 0 | BI9: =IFERROR(AP9/SUM($AO9:$BG9),"-") -> 0 | BJ9: =IFERROR(AQ9/SUM($AO9:$BG9),"-") -> 0 | BK9: =IFERROR(AR9/SUM($AO9:$BG9),"-") -> 0 | BL9: =IFERROR(AS9/SUM($AO9:$BG9),"-") -> 0 | BM9: =IFERROR(AT9/SUM($AO9:$BG9),"-") -> 0 | BN9: =IFERROR(AU9/SUM($AO9:$BG9),"-") -> 1 | BO9: =IFERROR(AV9/SUM($AO9:$BG9),"-") -> 0 | ... BZ9: =IFERROR(BG9/SUM($AO9:$BG9),"-") -> 0
A10: 10 | B10: 10-9 | C10: 2023 | D10: Albertslund Varmeværk | E10: 2620 | F10: Albertslund | G10: 165 | H10: 2 | I10: Storkøbenhavns Fjernvarme | J10: 10 | K10: 66137112 | L10: Albertslund Kommune | M10: 1 | N10: FJ | O10: Fjernvarmeværk | P10: Kedel 8B | Q10: Kedel | R10: 353000 | S10: 350030 | T10: fvv | U10: 30317 | W10: HO | X10: BOILER | Y10: YES | Z10: NATURAL GAS | AA10: ACTIVE | AB10: HOB_NG | AD10: 12.6 | AE10: 0 | AF10: 11.6 | AG10: 12.077912 | AH10: 8.715 | AI10: 8.715 | AJ10: 0 | AK10: 0 | AL10: 1 | AM10: 0 | AN10: 0 | AR10: 0.060979 | AU10: 12.016933 | BH10: =IFERROR(AO10/SUM($AO10:$BG10),"-") -> 0 | BI10: =IFERROR(AP10/SUM($AO10:$BG10),"-") -> 0 | BJ10: =IFERROR(AQ10/SUM($AO10:$BG10),"-") -> 0 | BK10: =IFERROR(AR10/SUM($AO10:$BG10),"-") -> 0.0050488032 | BL10: =IFERROR(AS10/SUM($AO10:$BG10),"-") -> 0 | BM10: =IFERROR(AT10/SUM($AO10:$BG10),"-") -> 0 | BN10: =IFERROR(AU10/SUM($AO10:$BG10),"-") -> 0.9949512 | BO10: =IFERROR(AV10/SUM($AO10:$BG10),"-") -> 0 | ... BZ10: =IFERROR(BG10/SUM($AO10:$BG10),"-") -> 0
A11: 73 | B11: 73-1 | C11: 2023 | D11: CTR, Nybrovej Centralen | E11: 2820 | F11: Gentofte | G11: 157 | H11: 2 | I11: Storkøbenhavns Fjernvarme | J11: 77 | K11: 74132111 | L11: CTR I/S | M11: 1 | N11: FJ | O11: Fjernvarmeværk | P11: NYC 1 kedel | Q11: Kedel | R11: 353000 | S11: 350030 | T11: fvv | U11: 31413 | W11: HO | X11: BOILER | Y11: YES | Z11: SPLIT | AA11: ACTIVE | AB11: ?? | AD11: 12.7 | AE11: 0 | AF11: 11.6 | AG11: 2.1920035 | AH11: 1.73175 | AI11: 1.73175 | AJ11: 0 | AK11: 0 | AL11: 1 | AM11: 0 | AN11: 0 | AR11: 0.26138469 | AU11: 1.9306188 | BH11: =IFERROR(AO11/SUM($AO11:$BG11),"-") -> 0 | BI11: =IFERROR(AP11/SUM($AO11:$BG11),"-") -> 0 | BJ11: =IFERROR(AQ11/SUM($AO11:$BG11),"-") -> 0 | BK11: =IFERROR(AR11/SUM($AO11:$BG11),"-") -> 0.11924465 | BL11: =IFERROR(AS11/SUM($AO11:$BG11),"-") -> 0 | BM11: =IFERROR(AT11/SUM($AO11:$BG11),"-") -> 0 | BN11: =IFERROR(AU11/SUM($AO11:$BG11),"-") -> 0.88075535 | BO11: =IFERROR(AV11/SUM($AO11:$BG11),"-") -> 0 | ... BZ11: =IFERROR(BG11/SUM($AO11:$BG11),"-") -> 0
A12: 73 | B12: 73-2 | C12: 2023 | D12: CTR, Nybrovej Centralen | E12: 2820 | F12: Gentofte | G12: 157 | H12: 2 | I12: Storkøbenhavns Fjernvarme | J12: 77 | K12: 74132111 | L12: CTR I/S | M12: 1 | N12: FJ | O12: Fjernvarmeværk | P12: NYC 2 kedel | Q12: Kedel | R12: 353000 | S12: 350030 | T12: fvv | U12: 31413 | W12: HO | X12: BOILER | Y12: YES | Z12: GAS OIL | AA12: ACTIVE | AB12: HOB_GO | AD12: 12.7 | AE12: 0 | AF12: 11.6 | AG12: 1.0842066 | AH12: 0.85654 | AI12: 0.85654 | AJ12: 0 | AK12: 0 | AL12: 1 | AM12: 0 | AN12: 0 | AR12: 1.0842066 | BH12: =IFERROR(AO12/SUM($AO12:$BG12),"-") -> 0 | BI12: =IFERROR(AP12/SUM($AO12:$BG12),"-") -> 0 | BJ12: =IFERROR(AQ12/SUM($AO12:$BG12),"-") -> 0 | BK12: =IFERROR(AR12/SUM($AO12:$BG12),"-") -> 1 | BL12: =IFERROR(AS12/SUM($AO12:$BG12),"-") -> 0 | BM12: =IFERROR(AT12/SUM($AO12:$BG12),"-") -> 0 | BN12: =IFERROR(AU12/SUM($AO12:$BG12),"-") -> 0 | BO12: =IFERROR(AV12/SUM($AO12:$BG12),"-") -> 0 | ... BZ12: =IFERROR(BG12/SUM($AO12:$BG12),"-") -> 0
A13: 73 | B13: 73-3 | C13: 2023 | D13: CTR, Nybrovej Centralen | E13: 2820 | F13: Gentofte | G13: 157 | H13: 2 | I13: Storkøbenhavns Fjernvarme | J13: 77 | K13: 74132111 | L13: CTR I/S | M13: 1 | N13: FJ | O13: Fjernvarmeværk | P13: Elkedel | Q13: Elpatron | R13: 353000 | S13: 350030 | T13: fvv | U13: 43831 | W13: HO | X13: BOILER | Y13: YES | Z13: ELECTRICITY | AA13: ACTIVE | AB13: HOB_EL | AD13: 40 | AE13: 0 | AF13: 40 | AG13: 40.644708 | AH13: 40.644708 | AI13: 40.644708 | AJ13: 0 | AK13: 0 | AL13: 1 | AM13: 0 | AN13: 0 | BF13: 40.644708 | BH13: =IFERROR(AO13/SUM($AO13:$BG13),"-") -> 0 | BI13: =IFERROR(AP13/SUM($AO13:$BG13),"-") -> 0 | BJ13: =IFERROR(AQ13/SUM($AO13:$BG13),"-") -> 0 | BK13: =IFERROR(AR13/SUM($AO13:$BG13),"-") -> 0 | BL13: =IFERROR(AS13/SUM($AO13:$BG13),"-") -> 0 | BM13: =IFERROR(AT13/SUM($AO13:$BG13),"-") -> 0 | BN13: =IFERROR(AU13/SUM($AO13:$BG13),"-") -> 0 | BO13: =IFERROR(AV13/SUM($AO13:$BG13),"-") -> 0 | ... BZ13: =IFERROR(BG13/SUM($AO13:$BG13),"-") -> 0
A14: 74 | B14: 74-1 | C14: 2023 | D14: CTR, Spidslastcentral Phistersvej | E14: 2900 | F14: Hellerup | G14: 157 | H14: 2 | I14: Storkøbenhavns Fjernvarme | J14: 77 | K14: 74132111 | L14: CTR I/S | M14: 1 | N14: FJ | O14: Fjernvarmeværk | P14: PHC 1 kedel | Q14: Kedel | R14: 353000 | S14: 350030 | T14: fvv | U14: 32143 | W14: HO | X14: BOILER | Y14: YES | Z14: GAS OIL | AA14: ACTIVE | AB14: HOB_GO | AD14: 14.9 | AE14: 0 | AF14: 13.6 | AG14: 41.784748 | AH14: 38.63924 | AI14: 38.63924 | AJ14: 0 | AK14: 0 | AL14: 1 | AM14: 0 | AN14: 0 | AR14: 41.784748 | BH14: =IFERROR(AO14/SUM($AO14:$BG14),"-") -> 0 | BI14: =IFERROR(AP14/SUM($AO14:$BG14),"-") -> 0 | BJ14: =IFERROR(AQ14/SUM($AO14:$BG14),"-") -> 0 | BK14: =IFERROR(AR14/SUM($AO14:$BG14),"-") -> 1 | BL14: =IFERROR(AS14/SUM($AO14:$BG14),"-") -> 0 | BM14: =IFERROR(AT14/SUM($AO14:$BG14),"-") -> 0 | BN14: =IFERROR(AU14/SUM($AO14:$BG14),"-") -> 0 | BO14: =IFERROR(AV14/SUM($AO14:$BG14),"-") -> 0 | ... BZ14: =IFERROR(BG14/SUM($AO14:$BG14),"-") -> 0
A15: 74 | B15: 74-2 | C15: 2023 | D15: CTR, Spidslastcentral Phistersvej | E15: 2900 | F15: Hellerup | G15: 157 | H15: 2 | I15: Storkøbenhavns Fjernvarme | J15: 77 | K15: 74132111 | L15: CTR I/S | M15: 1 | N15: FJ | O15: Fjernvarmeværk | P15: PHC2 kedel | Q15: Kedel | R15: 353000 | S15: 350030 | T15: fvv | U15: 32143 | W15: HO | X15: BOILER | Y15: YES | Z15: GAS OIL | AA15: ACTIVE | AB15: HOB_GO | AD15: 14.9 | AE15: 0 | AF15: 13.6 | AG15: 43.005153 | AH15: 39.76776 | AI15: 39.76776 | AJ15: 0 | AK15: 0 | AL15: 1 | AM15: 0 | AN15: 0 | AR15: 43.005153 | BH15: =IFERROR(AO15/SUM($AO15:$BG15),"-") -> 0 | BI15: =IFERROR(AP15/SUM($AO15:$BG15),"-") -> 0 | BJ15: =IFERROR(AQ15/SUM($AO15:$BG15),"-") -> 0 | BK15: =IFERROR(AR15/SUM($AO15:$BG15),"-") -> 1 | BL15: =IFERROR(AS15/SUM($AO15:$BG15),"-") -> 0 | BM15: =IFERROR(AT15/SUM($AO15:$BG15),"-") -> 0 | BN15: =IFERROR(AU15/SUM($AO15:$BG15),"-") -> 0 | BO15: =IFERROR(AV15/SUM($AO15:$BG15),"-") -> 0 | ... BZ15: =IFERROR(BG15/SUM($AO15:$BG15),"-") -> 0
A16: 121 | B16: 121-10 | C16: 2023 | D16: Frederiksberg Varmecentral | E16: 2000 | F16: Frederiksberg | G16: 147 | H16: 2 | I16: Storkøbenhavns Fjernvarme | J16: 77 | K16: 74132111 | L16: CTR I/S | M16: 1 | N16: FJ | O16: Fjernvarmeværk | P16: FVC2-4 kedel | Q16: Kedel | R16: 353000 | S16: 350030 | T16: fvv | U16: 36404 | W16: HO | X16: BOILER | Y16: YES | Z16: GAS OIL | AA16: ACTIVE | AB16: HOB_GO | AD16: 54 | AE16: 0 | AF16: 50 | AG16: 1.1959058 | AH16: 0.87421 | AI16: 0.87421 | AJ16: 0 | AK16: 0 | AL16: 1 | AM16: 0 | AN16: 0 | AR16: 1.1959058 | BH16: =IFERROR(AO16/SUM($AO16:$BG16),"-") -> 0 | BI16: =IFERROR(AP16/SUM($AO16:$BG16),"-") -> 0 | BJ16: =IFERROR(AQ16/SUM($AO16:$BG16),"-") -> 0 | BK16: =IFERROR(AR16/SUM($AO16:$BG16),"-") -> 1 | BL16: =IFERROR(AS16/SUM($AO16:$BG16),"-") -> 0 | BM16: =IFERROR(AT16/SUM($AO16:$BG16),"-") -> 0 | BN16: =IFERROR(AU16/SUM($AO16:$BG16),"-") -> 0 | BO16: =IFERROR(AV16/SUM($AO16:$BG16),"-") -> 0 | ... BZ16: =IFERROR(BG16/SUM($AO16:$BG16),"-") -> 0
A17: 121 | B17: 121-8 | C17: 2023 | D17: Frederiksberg Varmecentral | E17: 2000 | F17: Frederiksberg | G17: 147 | H17: 2 | I17: Storkøbenhavns Fjernvarme | J17: 77 | K17: 74132111 | L17: CTR I/S | M17: 1 | N17: FJ | O17: Fjernvarmeværk | P17: FVC2-2 kedel | Q17: Kedel | R17: 353000 | S17: 350030 | T17: fvv | U17: 35065 | W17: HO | X17: BOILER | Y17: YES | Z17: GAS OIL | AA17: ACTIVE | AB17: HOB_GO | AD17: 54 | AE17: 0 | AF17: 50 | AG17: 7.6727723 | AH17: 5.60873 | AI17: 5.60873 | AJ17: 0 | AK17: 0 | AL17: 1 | AM17: 0 | AN17: 0 | AR17: 7.6727723 | BH17: =IFERROR(AO17/SUM($AO17:$BG17),"-") -> 0 | BI17: =IFERROR(AP17/SUM($AO17:$BG17),"-") -> 0 | BJ17: =IFERROR(AQ17/SUM($AO17:$BG17),"-") -> 0 | BK17: =IFERROR(AR17/SUM($AO17:$BG17),"-") -> 1 | BL17: =IFERROR(AS17/SUM($AO17:$BG17),"-") -> 0 | BM17: =IFERROR(AT17/SUM($AO17:$BG17),"-") -> 0 | BN17: =IFERROR(AU17/SUM($AO17:$BG17),"-") -> 0 | BO17: =IFERROR(AV17/SUM($AO17:$BG17),"-") -> 0 | ... BZ17: =IFERROR(BG17/SUM($AO17:$BG17),"-") -> 0
A18: 121 | B18: 121-7 | C18: 2023 | D18: Frederiksberg Varmecentral | E18: 2000 | F18: Frederiksberg | G18: 147 | H18: 2 | I18: Storkøbenhavns Fjernvarme | J18: 77 | K18: 74132111 | L18: CTR I/S | M18: 1 | N18: FJ | O18: Fjernvarmeværk | P18: FVC2-1 kedel | Q18: Kedel | R18: 353000 | S18: 350030 | T18: fvv | U18: 35065 | W18: HO | X18: BOILER | Y18: YES | Z18: GAS OIL | AA18: ACTIVE | AB18: HOB_GO | AD18: 54 | AE18: 0 | AF18: 50 | AG18: 4.5234222 | AH18: 3.30659 | AI18: 3.30659 | AJ18: 0 | AK18: 0 | AL18: 1 | AM18: 0 | AN18: 0 | AR18: 4.5234222 | BH18: =IFERROR(AO18/SUM($AO18:$BG18),"-") -> 0 | BI18: =IFERROR(AP18/SUM($AO18:$BG18),"-") -> 0 | BJ18: =IFERROR(AQ18/SUM($AO18:$BG18),"-") -> 0 | BK18: =IFERROR(AR18/SUM($AO18:$BG18),"-") -> 1 | BL18: =IFERROR(AS18/SUM($AO18:$BG18),"-") -> 0 | BM18: =IFERROR(AT18/SUM($AO18:$BG18),"-") -> 0 | BN18: =IFERROR(AU18/SUM($AO18:$BG18),"-") -> 0 | BO18: =IFERROR(AV18/SUM($AO18:$BG18),"-") -> 0 | ... BZ18: =IFERROR(BG18/SUM($AO18:$BG18),"-") -> 0
A19: 121 | B19: 121-9 | C19: 2023 | D19: Frederiksberg Varmecentral | E19: 2000 | F19: Frederiksberg | G19: 147 | H19: 2 | I19: Storkøbenhavns Fjernvarme | J19: 77 | K19: 74132111 | L19: CTR I/S | M19: 1 | N19: FJ | O19: Fjernvarmeværk | P19: FVC2-3 kedel | Q19: Kedel | R19: 353000 | S19: 350030 | T19: fvv | U19: 36404 | W19: HO | X19: BOILER | Y19: YES | Z19: GAS OIL | AA19: ACTIVE | AB19: HOB_GO | AD19: 54 | AE19: 0 | AF19: 50 | AG19: 9.0294834 | AH19: 6.60047 | AI19: 6.60047 | AJ19: 0 | AK19: 0 | AL19: 1 | AM19: 0 | AN19: 0 | AR19: 9.0294834 | BH19: =IFERROR(AO19/SUM($AO19:$BG19),"-") -> 0 | BI19: =IFERROR(AP19/SUM($AO19:$BG19),"-") -> 0 | BJ19: =IFERROR(AQ19/SUM($AO19:$BG19),"-") -> 0 | BK19: =IFERROR(AR19/SUM($AO19:$BG19),"-") -> 1 | BL19: =IFERROR(AS19/SUM($AO19:$BG19),"-") -> 0 | BM19: =IFERROR(AT19/SUM($AO19:$BG19),"-") -> 0 | BN19: =IFERROR(AU19/SUM($AO19:$BG19),"-") -> 0 | BO19: =IFERROR(AV19/SUM($AO19:$BG19),"-") -> 0 | ... BZ19: =IFERROR(BG19/SUM($AO19:$BG19),"-") -> 0
A20: 244 | B20: 244-2 | C20: 2023 | D20: I/S Amager Ressourcecenter | E20: 2300 | F20: København S | G20: 101 | H20: 2 | I20: Storkøbenhavns Fjernvarme | J20: 236 | K20: 34208115 | L20: I/S Amager Ressourcecenter | M20: 1 | N20: ER | O20: Erhvervsværk | P20: 2 ovne &#43; 1 turbine | Q20: Dampturbine | R20: 382120 | S20: 383900 | T20: pev | U20: 42835 | W20: CHP | X20: STEAM_TURBINE | Y20: YES | Z20: MUNICIPAL WASTE | AA20: ACTIVE | AB20: ARC | AC20: assumed to be mono-fuel | AD20: 224 | AE20: 62 | AF20: 190 | AG20: 7239.6378 | AH20: 4677.9444 | AI20: 4677.9084 | AJ20: 1209.5705 | AK20: 1024.5154 | AL20: 0.51692182 | AM20: 0.48307421 | AN20: 3.9781e-06 | AR20: 51.516602 | AV20: 5550.5853 | AZ20: 1637.5359 | BH20: =IFERROR(AO20/SUM($AO20:$BG20),"-") -> 0 | BI20: =IFERROR(AP20/SUM($AO20:$BG20),"-") -> 0 | BJ20: =IFERROR(AQ20/SUM($AO20:$BG20),"-") -> 0 | BK20: =IFERROR(AR20/SUM($AO20:$BG20),"-") -> 0.0071159087 | BL20: =IFERROR(AS20/SUM($AO20:$BG20),"-") -> 0 | BM20: =IFERROR(AT20/SUM($AO20:$BG20),"-") -> 0 | BN20: =IFERROR(AU20/SUM($AO20:$BG20),"-") -> 0 | BO20: =IFERROR(AV20/SUM($AO20:$BG20),"-") -> 0.76669378 | ... BZ20: =IFERROR(BG20/SUM($AO20:$BG20),"-") -> 0
A21: 255 | B21: 255-2 | C21: 2023 | D21: ARGO Roskilde KraftVarmeVærk | E21: 4000 | F21: Roskilde | G21: 265 | H21: 2 | I21: Storkøbenhavns Fjernvarme | J21: 245 | K21: 13507406 | L21: ARGO I/S | M21: 1 | N21: ER | O21: Erhvervsværk | P21: Anlæg 5 | Q21: Dampturbine | R21: 382110 | S21: 383900 | T21: pev | U21: 36161 | W21: CHP | X21: STEAM_TURBINE | Y21: YES | Z21: MUNICIPAL WASTE | AA21: ACTIVE | AB21: ARGO5 | AD21: 65.1 | AE21: 13.7 | AF21: 45 | AG21: 1820.0965 | AH21: 1156.78 | AI21: 1156.78 | AJ21: 326.5848 | AK21: 281.97056 | AL21: 0.50844778 | AM21: 0.49155222 | AN21: 0 | AU21: 19.824354 | AV21: 1800.2721 | BH21: =IFERROR(AO21/SUM($AO21:$BG21),"-") -> 0 | BI21: =IFERROR(AP21/SUM($AO21:$BG21),"-") -> 0 | BJ21: =IFERROR(AQ21/SUM($AO21:$BG21),"-") -> 0 | BK21: =IFERROR(AR21/SUM($AO21:$BG21),"-") -> 0 | BL21: =IFERROR(AS21/SUM($AO21:$BG21),"-") -> 0 | BM21: =IFERROR(AT21/SUM($AO21:$BG21),"-") -> 0 | BN21: =IFERROR(AU21/SUM($AO21:$BG21),"-") -> 0.010891925 | BO21: =IFERROR(AV21/SUM($AO21:$BG21),"-") -> 0.98910808 | ... BZ21: =IFERROR(BG21/SUM($AO21:$BG21),"-") -> 0
A22: 255 | B22: 255-3 | C22: 2023 | D22: ARGO Roskilde KraftVarmeVærk | E22: 4000 | F22: Roskilde | G22: 265 | H22: 2 | I22: Storkøbenhavns Fjernvarme | J22: 245 | K22: 13507406 | L22: ARGO I/S | M22: 1 | N22: ER | O22: Erhvervsværk | P22: Anlæg 6 (Energitårnet) | Q22: Dampturbine | R22: 382110 | S22: 383900 | T22: pev | U22: 41514 | W22: CHP | X22: STEAM_TURBINE | Y22: YES | Z22: MUNICIPAL WASTE | AA22: ACTIVE | AB22: ARGO6 | AD22: 73 | AE22: 19.4 | AF22: 51.8 | AG22: 2118.7322 | AH22: 1563.099 | AI22: 1563.099 | AJ22: 432.0684 | AK22: 370.78956 | AL22: 0.59020163 | AM22: 0.40979837 | AN22: 0 | AR22: 6.8518874 | AV22: 2111.8803 | BH22: =IFERROR(AO22/SUM($AO22:$BG22),"-") -> 0 | BI22: =IFERROR(AP22/SUM($AO22:$BG22),"-") -> 0 | BJ22: =IFERROR(AQ22/SUM($AO22:$BG22),"-") -> 0 | BK22: =IFERROR(AR22/SUM($AO22:$BG22),"-") -> 0.0032339563 | BL22: =IFERROR(AS22/SUM($AO22:$BG22),"-") -> 0 | BM22: =IFERROR(AT22/SUM($AO22:$BG22),"-") -> 0 | BN22: =IFERROR(AU22/SUM($AO22:$BG22),"-") -> 0 | BO22: =IFERROR(AV22/SUM($AO22:$BG22),"-") -> 0.99676604 | ... BZ22: =IFERROR(BG22/SUM($AO22:$BG22),"-") -> 0
A23: 269 | B23: 269-1 | C23: 2023 | D23: Avedøreværket | E23: 2650 | F23: Hvidovre | G23: 167 | H23: 2 | I23: Storkøbenhavns Fjernvarme | J23: 2161 | K23: 27446469 | L23: Ørsted Bioenergy & Thermal Power A/S | M23: 1 | N23: CE | O23: Centralt værk | P23: AVV1 Dampturbine | Q23: Dampturbine | R23: 351100 | S23: 350010 | T23: cev | U23: 32874 | W23: CHP | X23: STEAM_TURBINE | Y23: YES | Z23: WOOD PELLETS | AA23: ACTIVE | AB23: AVV1 | AD23: 624 | AE23: 257.6 | AF23: 353.5 | AG23: 8765.4588 | AH23: 3288.217 | AI23: 3277.0316 | AJ23: 3235.3596 | AK23: 2978.7008 | AL23: 0.30010678 | AM23: 0.69989322 | AN23: 0 | AO23: 0.019365693 | AP23: 35.76072 | AR23: 14.923713 | BA23: 8714.755 | BH23: =IFERROR(AO23/SUM($AO23:$BG23),"-") -> 2.2093188e-06 | BI23: =IFERROR(AP23/SUM($AO23:$BG23),"-") -> 0.0040797317 | BJ23: =IFERROR(AQ23/SUM($AO23:$BG23),"-") -> 0 | BK23: =IFERROR(AR23/SUM($AO23:$BG23),"-") -> 0.0017025593 | BL23: =IFERROR(AS23/SUM($AO23:$BG23),"-") -> 0 | BM23: =IFERROR(AT23/SUM($AO23:$BG23),"-") -> 0 | BN23: =IFERROR(AU23/SUM($AO23:$BG23),"-") -> 0 | BO23: =IFERROR(AV23/SUM($AO23:$BG23),"-") -> 0 | ... BZ23: =IFERROR(BG23/SUM($AO23:$BG23),"-") -> 0
A24: 269 | B24: 269-2 | C24: 2023 | D24: Avedøreværket | E24: 2650 | F24: Hvidovre | G24: 167 | H24: 2 | I24: Storkøbenhavns Fjernvarme | J24: 2161 | K24: 27446469 | L24: Ørsted Bioenergy & Thermal Power A/S | M24: 1 | N24: CE | O24: Centralt værk | P24: AVV2 Kombianlæg | Q24: Kombianlæg | R24: 351100 | S24: 350010 | T24: cev | U24: 36892 | W24: CHP | X24: COMBINED_CYCLE | Y24: YES | Z24: WOOD PELLETS | AA24: ACTIVE | AB24: AVV2 | AC24: assumed to be mono-fuel | AD24: 1168 | AE24: 548 | AF24: 583 | AG24: 13289.213 | AH24: 5398.865 | AI24: 5371.4244 | AJ24: 4807.1988 | AK24: 4411.877 | AL24: 0.32500735 | AM24: 0.67499265 | AN24: 0 | AO24: 0.01889758 | AR24: 0.315656 | AU24: 434.84918 | AX24: 1609.3695 | BA24: 11244.66 | BH24: =IFERROR(AO24/SUM($AO24:$BG24),"-") -> 1.422024e-06 | BI24: =IFERROR(AP24/SUM($AO24:$BG24),"-") -> 0 | BJ24: =IFERROR(AQ24/SUM($AO24:$BG24),"-") -> 0 | BK24: =IFERROR(AR24/SUM($AO24:$BG24),"-") -> 2.3752798e-05 | BL24: =IFERROR(AS24/SUM($AO24:$BG24),"-") -> 0 | BM24: =IFERROR(AT24/SUM($AO24:$BG24),"-") -> 0 | BN24: =IFERROR(AU24/SUM($AO24:$BG24),"-") -> 0.032721966 | BO24: =IFERROR(AV24/SUM($AO24:$BG24),"-") -> 0 | ... BZ24: =IFERROR(BG24/SUM($AO24:$BG24),"-") -> 0
A25: 269 | B25: 269-7 | C25: 2023 | D25: Avedøreværket | E25: 2650 | F25: Hvidovre | G25: 167 | H25: 2 | I25: Storkøbenhavns Fjernvarme | J25: 2161 | K25: 27446469 | L25: Ørsted Bioenergy & Thermal Power A/S | M25: 1 | N25: CE | O25: Centralt værk | P25: AVV EL-patron Damppudegenerator | Q25: Elpatron | R25: 351100 | S25: 350010 | T25: fvv | U25: 33756 | W25: HO | X25: BOILER | Y25: YES | Z25: ELECTRICITY | AA25: ACTIVE | AB25: HOB_EL | AD25: 0.015 | AE25: 0 | AF25: 0.015 | AG25: 0 | AH25: 0 | AI25: 0 | AJ25: 0 | AK25: 0 | AL25: 1 | AM25: 0 | AN25: 0 | BF25: 0 | BH25: =IFERROR(AO25/SUM($AO25:$BG25),"-") -> - | BI25: =IFERROR(AP25/SUM($AO25:$BG25),"-") -> - | BJ25: =IFERROR(AQ25/SUM($AO25:$BG25),"-") -> - | BK25: =IFERROR(AR25/SUM($AO25:$BG25),"-") -> - | BL25: =IFERROR(AS25/SUM($AO25:$BG25),"-") -> - | BM25: =IFERROR(AT25/SUM($AO25:$BG25),"-") -> - | BN25: =IFERROR(AU25/SUM($AO25:$BG25),"-") -> - | BO25: =IFERROR(AV25/SUM($AO25:$BG25),"-") -> - | ... BZ25: =IFERROR(BG25/SUM($AO25:$BG25),"-") -> -
A26: 285 | B26: 285-11 | C26: 2023 | D26: I/S Vestforbrænding | E26: 2600 | F26: Glostrup | G26: 161 | H26: 2 | I26: Storkøbenhavns Fjernvarme | J26: 259 | K26: 10866111 | L26: I/S VESTFORBRÆNDING | M26: 1 | N26: ER | O26: Erhvervsværk | P26: Anlæg 6 - dampturbine | Q26: Dampturbine | R26: 382120 | S26: 383900 | T26: pev | U26: 38261 | W26: CHP | X26: STEAM_TURBINE | Y26: YES | Z26: MUNICIPAL WASTE | AA26: ACTIVE | AB26: VF6 | AD26: 111.76 | AE26: 22 | AF26: 73 | AG26: 2692.3832 | AH26: 2297.502 | AI26: 2281.8276 | AJ26: 435.9132 | AK26: 370.4976 | AL26: 0.63291947 | AM26: 0.36273286 | AN26: 0.0043476698 | AU26: 25.160929 | AV26: 2667.2223 | BH26: =IFERROR(AO26/SUM($AO26:$BG26),"-") -> 0 | BI26: =IFERROR(AP26/SUM($AO26:$BG26),"-") -> 0 | BJ26: =IFERROR(AQ26/SUM($AO26:$BG26),"-") -> 0 | BK26: =IFERROR(AR26/SUM($AO26:$BG26),"-") -> 0 | BL26: =IFERROR(AS26/SUM($AO26:$BG26),"-") -> 0 | BM26: =IFERROR(AT26/SUM($AO26:$BG26),"-") -> 0 | BN26: =IFERROR(AU26/SUM($AO26:$BG26),"-") -> 0.0093452258 | BO26: =IFERROR(AV26/SUM($AO26:$BG26),"-") -> 0.99065477 | ... BZ26: =IFERROR(BG26/SUM($AO26:$BG26),"-") -> 0
A27: 285 | B27: 285-10 | C27: 2023 | D27: I/S Vestforbrænding | E27: 2600 | F27: Glostrup | G27: 161 | H27: 2 | I27: Storkøbenhavns Fjernvarme | J27: 259 | K27: 10866111 | L27: I/S VESTFORBRÆNDING | M27: 1 | N27: ER | O27: Erhvervsværk | P27: Anlæg 5 - dampturbine | Q27: Dampturbine | R27: 382120 | S27: 383900 | T27: pev | U27: 36136 | W27: CHP | X27: STEAM_TURBINE | Y27: YES | Z27: MUNICIPAL WASTE | AA27: ACTIVE | AB27: VF5 | AD27: 84.71 | AE27: 17 | AF27: 69 | AG27: 1981.0623 | AH27: 1582.632 | AI27: 1570.9356 | AJ27: 318.9276 | AK27: 265.7052 | AL27: 0.6343811 | AM27: 0.36089561 | AN27: 0.0047232841 | AR27: 18.171742 | AV27: 1962.8905 | BH27: =IFERROR(AO27/SUM($AO27:$BG27),"-") -> 0 | BI27: =IFERROR(AP27/SUM($AO27:$BG27),"-") -> 0 | BJ27: =IFERROR(AQ27/SUM($AO27:$BG27),"-") -> 0 | BK27: =IFERROR(AR27/SUM($AO27:$BG27),"-") -> 0.0091727262 | BL27: =IFERROR(AS27/SUM($AO27:$BG27),"-") -> 0 | BM27: =IFERROR(AT27/SUM($AO27:$BG27),"-") -> 0 | BN27: =IFERROR(AU27/SUM($AO27:$BG27),"-") -> 0 | BO27: =IFERROR(AV27/SUM($AO27:$BG27),"-") -> 0.99082727 | ... BZ27: =IFERROR(BG27/SUM($AO27:$BG27),"-") -> 0
A28: 285 | B28: 285-5 | C28: 2023 | D28: I/S Vestforbrænding | E28: 2600 | F28: Glostrup | G28: 161 | H28: 2 | I28: Storkøbenhavns Fjernvarme | J28: 259 | K28: 10866111 | L28: I/S VESTFORBRÆNDING | M28: 1 | N28: ER | O28: Erhvervsværk | P28: Spidslastkedel 1 på Vestforbr - kedel | Q28: Kedel | R28: 382120 | S28: 383900 | T28: pvp | U28: 26299 | W28: HO | X28: BOILER | Y28: YES | Z28: SPLIT | AA28: ACTIVE | AB28: ?? | AD28: 22.22 | AE28: 0 | AF28: 20.35 | AG28: 50.998005 | AH28: 50.9436 | AI28: 49.5972 | AJ28: 0 | AK28: 0 | AL28: 0.97357077 | AM28: 0 | AN28: 0.026429228 | AR28: 9.5417787 | AU28: 41.456226 | BH28: =IFERROR(AO28/SUM($AO28:$BG28),"-") -> 0 | BI28: =IFERROR(AP28/SUM($AO28:$BG28),"-") -> 0 | BJ28: =IFERROR(AQ28/SUM($AO28:$BG28),"-") -> 0 | BK28: =IFERROR(AR28/SUM($AO28:$BG28),"-") -> 0.18710102 | BL28: =IFERROR(AS28/SUM($AO28:$BG28),"-") -> 0 | BM28: =IFERROR(AT28/SUM($AO28:$BG28),"-") -> 0 | BN28: =IFERROR(AU28/SUM($AO28:$BG28),"-") -> 0.81289898 | BO28: =IFERROR(AV28/SUM($AO28:$BG28),"-") -> 0 | ... BZ28: =IFERROR(BG28/SUM($AO28:$BG28),"-") -> 0
A29: 285 | B29: 285-6 | C29: 2023 | D29: I/S Vestforbrænding | E29: 2600 | F29: Glostrup | G29: 161 | H29: 2 | I29: Storkøbenhavns Fjernvarme | J29: 259 | K29: 10866111 | L29: I/S VESTFORBRÆNDING | M29: 1 | N29: ER | O29: Erhvervsværk | P29: Spidslastkedel 2 på Vestforbr - kedel | Q29: Kedel | R29: 382120 | S29: 383900 | T29: pvp | U29: 26299 | W29: HO | X29: BOILER | Y29: YES | Z29: SPLIT | AA29: ACTIVE | AB29: ?? | AD29: 22.22 | AE29: 0 | AF29: 20.35 | AG29: 44.507155 | AH29: 44.46 | AI29: 43.1136 | AJ29: 0 | AK29: 0 | AL29: 0.9697166 | AM29: 0 | AN29: 0.030283401 | AR29: 8.325427 | AU29: 36.181728 | BH29: =IFERROR(AO29/SUM($AO29:$BG29),"-") -> 0 | BI29: =IFERROR(AP29/SUM($AO29:$BG29),"-") -> 0 | BJ29: =IFERROR(AQ29/SUM($AO29:$BG29),"-") -> 0 | BK29: =IFERROR(AR29/SUM($AO29:$BG29),"-") -> 0.18705817 | BL29: =IFERROR(AS29/SUM($AO29:$BG29),"-") -> 0 | BM29: =IFERROR(AT29/SUM($AO29:$BG29),"-") -> 0 | BN29: =IFERROR(AU29/SUM($AO29:$BG29),"-") -> 0.81294183 | BO29: =IFERROR(AV29/SUM($AO29:$BG29),"-") -> 0 | ... BZ29: =IFERROR(BG29/SUM($AO29:$BG29),"-") -> 0
A30: 285 | B30: 285-7 | C30: 2023 | D30: I/S Vestforbrænding | E30: 2600 | F30: Glostrup | G30: 161 | H30: 2 | I30: Storkøbenhavns Fjernvarme | J30: 259 | K30: 10866111 | L30: I/S VESTFORBRÆNDING | M30: 1 | N30: ER | O30: Erhvervsværk | P30: Spidslastkedel 3 på Vestforbr - kedel | Q30: Kedel | R30: 382120 | S30: 383900 | T30: pvp | U30: 29587 | W30: HO | X30: BOILER | Y30: YES | Z30: SPLIT | AA30: ACTIVE | AB30: ?? | AD30: 22.22 | AE30: 0 | AF30: 20.35 | AG30: 76.870031 | AH30: 62.6724 | AI30: 61.326 | AJ30: 0 | AK30: 0 | AL30: 0.97851686 | AM30: 0 | AN30: 0.021483141 | AR30: 11.736664 | AU30: 65.133367 | BH30: =IFERROR(AO30/SUM($AO30:$BG30),"-") -> 0 | BI30: =IFERROR(AP30/SUM($AO30:$BG30),"-") -> 0 | BJ30: =IFERROR(AQ30/SUM($AO30:$BG30),"-") -> 0 | BK30: =IFERROR(AR30/SUM($AO30:$BG30),"-") -> 0.15268192 | BL30: =IFERROR(AS30/SUM($AO30:$BG30),"-") -> 0 | BM30: =IFERROR(AT30/SUM($AO30:$BG30),"-") -> 0 | BN30: =IFERROR(AU30/SUM($AO30:$BG30),"-") -> 0.84731808 | BO30: =IFERROR(AV30/SUM($AO30:$BG30),"-") -> 0 | ... BZ30: =IFERROR(BG30/SUM($AO30:$BG30),"-") -> 0
A31: 298 | B31: 298-2 | C31: 2023 | D31: Ishøj Varmeværk Industrivangen | E31: 2635 | F31: Ishøj | G31: 183 | H31: 2 | I31: Storkøbenhavns Fjernvarme | J31: 267 | K31: 11931316 | L31: Ishøj Kommune | N31: FJ | O31: Fjernvarmeværk | P31: Kedel 2 Burmeister & Wain | Q31: Kedel | R31: 353000 | S31: 350030 | T31: fvv | U31: 30286 | W31: HO | X31: BOILER | Y31: NO | Z31: UNKNOWN | AA31: INOPERATIVE | AB31: - | AC31: inoperative, unknown fuel | AD31: 11 | AE31: 0 | AF31: 11 | AG31: 0 | AH31: 0 | AI31: 0 | AJ31: 0 | AK31: 0 | AL31: 1 | AM31: 0 | AN31: 0 | BA31: 0 | BH31: =IFERROR(AO31/SUM($AO31:$BG31),"-") -> - | BI31: =IFERROR(AP31/SUM($AO31:$BG31),"-") -> - | BJ31: =IFERROR(AQ31/SUM($AO31:$BG31),"-") -> - | BK31: =IFERROR(AR31/SUM($AO31:$BG31),"-") -> - | BL31: =IFERROR(AS31/SUM($AO31:$BG31),"-") -> - | BM31: =IFERROR(AT31/SUM($AO31:$BG31),"-") -> - | BN31: =IFERROR(AU31/SUM($AO31:$BG31),"-") -> - | BO31: =IFERROR(AV31/SUM($AO31:$BG31),"-") -> - | ... BZ31: =IFERROR(BG31/SUM($AO31:$BG31),"-") -> -
A32: 298 | B32: 298-4 | C32: 2023 | D32: Ishøj Varmeværk Industrivangen | E32: 2635 | F32: Ishøj | G32: 183 | H32: 2 | I32: Storkøbenhavns Fjernvarme | J32: 267 | K32: 11931316 | L32: Ishøj Kommune | N32: FJ | O32: Fjernvarmeværk | P32: Gaskedlen Viessmann | Q32: Kedel | R32: 353000 | S32: 350030 | T32: fvv | U32: 32874 | W32: HO | X32: BOILER | Y32: NO | Z32: NATURAL GAS | AA32: ACTIVE | AB32: HOB_NG_NOETS | AD32: 2.5 | AE32: 0 | AF32: 2.5 | AG32: 0.033066 | AH32: 0 | AI32: 0 | AJ32: 0 | AK32: 0 | AL32: 1 | AM32: 0 | AN32: 0 | AU32: 0.033066 | BH32: =IFERROR(AO32/SUM($AO32:$BG32),"-") -> 0 | BI32: =IFERROR(AP32/SUM($AO32:$BG32),"-") -> 0 | BJ32: =IFERROR(AQ32/SUM($AO32:$BG32),"-") -> 0 | BK32: =IFERROR(AR32/SUM($AO32:$BG32),"-") -> 0 | BL32: =IFERROR(AS32/SUM($AO32:$BG32),"-") -> 0 | BM32: =IFERROR(AT32/SUM($AO32:$BG32),"-") -> 0 | BN32: =IFERROR(AU32/SUM($AO32:$BG32),"-") -> 1 | BO32: =IFERROR(AV32/SUM($AO32:$BG32),"-") -> 0 | ... BZ32: =IFERROR(BG32/SUM($AO32:$BG32),"-") -> 0
A33: 298 | B33: 298-1 | C33: 2023 | D33: Ishøj Varmeværk Industrivangen | E33: 2635 | F33: Ishøj | G33: 183 | H33: 2 | I33: Storkøbenhavns Fjernvarme | J33: 267 | K33: 11931316 | L33: Ishøj Kommune | N33: FJ | O33: Fjernvarmeværk | P33: Kedel 1 Burmeister & Wain | Q33: Kedel | R33: 353000 | S33: 350030 | T33: fvv | U33: 30256 | W33: HO | X33: BOILER | Y33: NO | Z33: WOOD PELLETS | AA33: ACTIVE | AB33: HOB_WP | AD33: 11 | AE33: 0 | AF33: 11 | AG33: 116.6865 | AH33: 110.019 | AI33: 110.019 | AJ33: 0 | AK33: 0 | AL33: 1 | AM33: 0 | AN33: 0 | BA33: 116.6865 | BH33: =IFERROR(AO33/SUM($AO33:$BG33),"-") -> 0 | BI33: =IFERROR(AP33/SUM($AO33:$BG33),"-") -> 0 | BJ33: =IFERROR(AQ33/SUM($AO33:$BG33),"-") -> 0 | BK33: =IFERROR(AR33/SUM($AO33:$BG33),"-") -> 0 | BL33: =IFERROR(AS33/SUM($AO33:$BG33),"-") -> 0 | BM33: =IFERROR(AT33/SUM($AO33:$BG33),"-") -> 0 | BN33: =IFERROR(AU33/SUM($AO33:$BG33),"-") -> 0 | BO33: =IFERROR(AV33/SUM($AO33:$BG33),"-") -> 0 | ... BZ33: =IFERROR(BG33/SUM($AO33:$BG33),"-") -> 0
A34: 298 | B34: 298-3 | C34: 2023 | D34: Ishøj Varmeværk Industrivangen | E34: 2635 | F34: Ishøj | G34: 183 | H34: 2 | I34: Storkøbenhavns Fjernvarme | J34: 267 | K34: 11931316 | L34: Ishøj Kommune | N34: FJ | O34: Fjernvarmeværk | P34: Kedel 3 Burmeister & Wain | Q34: Kedel | R34: 353000 | S34: 350030 | T34: fvv | U34: 30286 | W34: HO | X34: BOILER | Y34: NO | Z34: UNKNOWN | AA34: INOPERATIVE | AB34: - | AC34: inoperative, unknown fuel | AD34: 11 | AE34: 0 | AF34: 11 | AG34: 0 | AH34: 0 | AI34: 0 | AJ34: 0 | AK34: 0 | AL34: 1 | AM34: 0 | AN34: 0 | BA34: 0 | BH34: =IFERROR(AO34/SUM($AO34:$BG34),"-") -> - | BI34: =IFERROR(AP34/SUM($AO34:$BG34),"-") -> - | BJ34: =IFERROR(AQ34/SUM($AO34:$BG34),"-") -> - | BK34: =IFERROR(AR34/SUM($AO34:$BG34),"-") -> - | BL34: =IFERROR(AS34/SUM($AO34:$BG34),"-") -> - | BM34: =IFERROR(AT34/SUM($AO34:$BG34),"-") -> - | BN34: =IFERROR(AU34/SUM($AO34:$BG34),"-") -> - | BO34: =IFERROR(AV34/SUM($AO34:$BG34),"-") -> - | ... BZ34: =IFERROR(BG34/SUM($AO34:$BG34),"-") -> -
A35: 330 | B35: 330-1 | C35: 2023 | D35: Amagerværket | E35: 2300 | F35: København S | G35: 101 | H35: 2 | I35: Storkøbenhavns Fjernvarme | J35: 2184 | K35: 35523294 | L35: HOFOR ENERGIPRODUKTION A/S | M35: 1 | N35: CE | O35: Centralt værk | P35: AMV1 | Q35: Dampturbine | R35: 351100 | S35: 350010 | T35: cev | U35: 25934 | W35: CHP | X35: STEAM_TURBINE | Y35: YES | Z35: WOOD PELLETS | AA35: ACTIVE | AB35: AMV1 | AD35: 362 | AE35: 64 | AF35: 251 | AG35: 4189.4044 | AH35: 3210.5916 | AI35: 3210.5916 | AJ35: 735.768 | AK35: 607.752 | AL35: 0.61308792 | AM35: 0.38691208 | AN35: 0 | AR35: 35.9544 | BA35: 4153.45 | BH35: =IFERROR(AO35/SUM($AO35:$BG35),"-") -> 0 | BI35: =IFERROR(AP35/SUM($AO35:$BG35),"-") -> 0 | BJ35: =IFERROR(AQ35/SUM($AO35:$BG35),"-") -> 0 | BK35: =IFERROR(AR35/SUM($AO35:$BG35),"-") -> 0.0085822223 | BL35: =IFERROR(AS35/SUM($AO35:$BG35),"-") -> 0 | BM35: =IFERROR(AT35/SUM($AO35:$BG35),"-") -> 0 | BN35: =IFERROR(AU35/SUM($AO35:$BG35),"-") -> 0 | BO35: =IFERROR(AV35/SUM($AO35:$BG35),"-") -> 0 | ... BZ35: =IFERROR(BG35/SUM($AO35:$BG35),"-") -> 0
A36: 330 | B36: 330-6 | C36: 2023 | D36: Amagerværket | E36: 2300 | F36: København S | G36: 101 | H36: 2 | I36: Storkøbenhavns Fjernvarme | J36: 2184 | K36: 35523294 | L36: HOFOR ENERGIPRODUKTION A/S | M36: 1 | N36: CE | O36: Centralt værk | P36: AMV4 | Q36: Dampturbine | R36: 351100 | S36: 350010 | T36: cev | U36: 43709 | W36: CHP | X36: STEAM_TURBINE | Y36: YES | Z36: WOOD CHIPS | AA36: ACTIVE | AB36: AMV4 | AD36: 500 | AE36: 150 | AF36: 400 | AG36: 9701.6458 | AH36: 7612.67 | AI36: 7612.67 | AJ36: 2448.4716 | AK36: 2144.4156 | AL36: 0.62774256 | AM36: 0.37225744 | AN36: 0 | AR36: 14.421378 | AY36: 9687.2245 | BH36: =IFERROR(AO36/SUM($AO36:$BG36),"-") -> 0 | BI36: =IFERROR(AP36/SUM($AO36:$BG36),"-") -> 0 | BJ36: =IFERROR(AQ36/SUM($AO36:$BG36),"-") -> 0 | BK36: =IFERROR(AR36/SUM($AO36:$BG36),"-") -> 0.0014864878 | BL36: =IFERROR(AS36/SUM($AO36:$BG36),"-") -> 0 | BM36: =IFERROR(AT36/SUM($AO36:$BG36),"-") -> 0 | BN36: =IFERROR(AU36/SUM($AO36:$BG36),"-") -> 0 | BO36: =IFERROR(AV36/SUM($AO36:$BG36),"-") -> 0 | ... BZ36: =IFERROR(BG36/SUM($AO36:$BG36),"-") -> 0
A37: 331 | B37: 331-6 | C37: 2023 | D37: H.C. Ørsted Værket | E37: 2450 | F37: København SV | G37: 101 | H37: 2 | I37: Storkøbenhavns Fjernvarme | J37: 2161 | K37: 27446469 | L37: Ørsted Bioenergy & Thermal Power A/S | M37: 1 | N37: CE | O37: Centralt værk | P37: HCV Kedel 22 | Q37: Kedel | R37: 351100 | S37: 350010 | T37: fvv | U37: 38718 | W37: HO | X37: BOILER | Y37: YES | Z37: NATURAL GAS | AA37: ACTIVE | AB37: HOB_NG | AD37: 106 | AE37: 0 | AF37: 99.6 | AG37: 188.27354 | AH37: 168.3829 | AI37: 168.3829 | AJ37: 0 | AK37: 0 | AL37: 1 | AM37: 0 | AN37: 0 | AU37: 188.27354 | BH37: =IFERROR(AO37/SUM($AO37:$BG37),"-") -> 0 | BI37: =IFERROR(AP37/SUM($AO37:$BG37),"-") -> 0 | BJ37: =IFERROR(AQ37/SUM($AO37:$BG37),"-") -> 0 | BK37: =IFERROR(AR37/SUM($AO37:$BG37),"-") -> 0 | BL37: =IFERROR(AS37/SUM($AO37:$BG37),"-") -> 0 | BM37: =IFERROR(AT37/SUM($AO37:$BG37),"-") -> 0 | BN37: =IFERROR(AU37/SUM($AO37:$BG37),"-") -> 1 | BO37: =IFERROR(AV37/SUM($AO37:$BG37),"-") -> 0 | ... BZ37: =IFERROR(BG37/SUM($AO37:$BG37),"-") -> 0
A38: 331 | B38: 331-2 | C38: 2023 | D38: H.C. Ørsted Værket | E38: 2450 | F38: København SV | G38: 101 | H38: 2 | I38: Storkøbenhavns Fjernvarme | J38: 2161 | K38: 27446469 | L38: Ørsted Bioenergy & Thermal Power A/S | M38: 1 | N38: CE | O38: Centralt værk | P38: HCV Blok 7 | Q38: Dampturbine | R38: 351100 | S38: 350010 | T38: cev | U38: 31048 | W38: CHP | X38: STEAM_TURBINE | Y38: YES | Z38: NATURAL GAS | AA38: ACTIVE | AB38: HCV7 | AD38: 200 | AE38: 44.2 | AF38: 142.7 | AG38: 0 | AH38: 0 | AI38: 0 | AJ38: 0 | AK38: 0 | AL38: 1 | AM38: 0 | AN38: 0 | AU38: 0 | BH38: =IFERROR(AO38/SUM($AO38:$BG38),"-") -> - | BI38: =IFERROR(AP38/SUM($AO38:$BG38),"-") -> - | BJ38: =IFERROR(AQ38/SUM($AO38:$BG38),"-") -> - | BK38: =IFERROR(AR38/SUM($AO38:$BG38),"-") -> - | BL38: =IFERROR(AS38/SUM($AO38:$BG38),"-") -> - | BM38: =IFERROR(AT38/SUM($AO38:$BG38),"-") -> - | BN38: =IFERROR(AU38/SUM($AO38:$BG38),"-") -> - | BO38: =IFERROR(AV38/SUM($AO38:$BG38),"-") -> - | ... BZ38: =IFERROR(BG38/SUM($AO38:$BG38),"-") -> -
