Workbook

Sheet DK-TaxRates
B2: CONVERSION FACTORS
C4: Value | D4: Units | E4: Notes
B5: Energy units | C5: 3.6 | D5: GJ/MWh
C6: =1/C5 -> 0.27777778 | D6: MWh/GJ
B7: Exchange rate | C7: 0.134 | D7: EUR/DKK
C8: 7.4634 | D8: DKK/EUR
B9: Share of biogenic municipal waste | C9: 0.6 | D9: - | E9: - Assumed from ranges found in technology catalogue (Chapter 8, Section Environment)
B10: CHP fuel allocation factor to heat | C10: =1/1.2 -> 0.83333333 | D10: MWhf/MWhh | E10: - How much fuel is allocated to heat, based on heat output
B13: ENERGY CONTENT
B15: Fuel | C15: Value | D15: Unit | E15: Note
B16: Biogas | C16: 0.03803 | D16: GJ/m3
B17: Electricity | C17: 0.001 | D17: MWh/kWh
B18: Industrial heat | C18: 1 | D18: MWh/MWh
B19: Gas oil | C19: 35.9 | D19: GJ/m3 | E19: - Source (skat)
B20: Municipal waste | C20: 11.7 | D20: GJ/ton
B21: Natural gas | C21: 0.03803 | D21: GJ/m3
B22: Wood chips | C22: 10.4 | D22: GJ/ton
B23: Wood pellets | C23: 17.5 | D23: GJ/ton
B24: *Source: SØB25
B26: CARBON CONTENT
B28: Fuel | C28: Value | D28: Unit | E28: Note
B29: Biogas | C29: 0 | D29: kg-CO2/GJ
B30: Electricity | C30: variable | D30: kg-CO2/GJ
B31: Industrial heat | C31: 0 | D31: kg-CO2/GJ | E31: - Assumed from otherwise unavoidable economic activity
B32: Gas oil | C32: 74.1 | D32: kg-CO2/GJ
B33: Municipal waste | C33: 37 | D33: kg-CO2/GJ | E33: - Corresponds to fossil-CO2 content only
B34: Natural gas | C34: 57.1 | D34: kg-CO2/GJ
B35: Wood chips | C35: 0 | D35: kg-CO2/GJ
B36: Wood pellets | C36: 0 | D36: kg-CO2/GJ
B37: *Source: SØB25, DEA Technology Catalogue (municipal waste)
B39: ENERGY AND ELECTRICITY TAX
B41: Fuel | C41: Tax rate | D41: Unit | E41: Note | G41: Tax rate | H41: Unit | K41: HEAT-ONLY | L41: COGENERATION
B42: Biogas | C42: 0.098 | D42: DKK/m3 | G42: =IFERROR(C42*(1/C16)*$C$5*$C$7,"-") -> 1.2431028 | H42: €/MWhf | K42: Heat | L42: Heat | M42: Electricity
B43: Electricity | C43: 0.004 | D43: DKK/kWh | G43: =IFERROR(C43*(1/C17)*$C$7,"-") -> 0.536 | H43: €/MWhf | J43: ETS | K43: ✓ | L43: ✓ | M43: ✗
B44: Industrial heat | C44: 0 | D44: DKK/GJ | E44: - Provider assumed part of energy efficiency program | G44: =IFERROR(C44*(1/C18)*$C$5*$C$7,"-") -> 0 | H44: €/MWhf | J44: non-ETS | K44: ✓ | L44: ✓ | M44: ✗
B45: Gas oil | C45: 1234 | D45: DKK/m3 | G45: =IFERROR(C45*(1/C19)*$C$5*$C$7,"-") -> 16.58166 | H45: €/MWhf | J45: *Tax coverage
B46: Municipal waste (Affaldsvarmeafgift) | C46: 28.8 | D46: DKK/GJ | E46: - Levied on heat output, biodegradable share is exempted | G46: =IFERROR(C46*$C$5*$C$7*(1-$C$9),"-") -> 5.557248 | H46: €/MWhh
B47: Municipal waste (Tillægsafgift) | C47: 14.5 | D47: DKK/GJ | E47: - Levied on fuel energy content, biodegradable share is exempted | G47: =C47*$C$5*$C$7*(1-$C$9) -> 2.79792 | H47: €/MWhf | K47: HEAT-ONLY | L47: COGENERATION
B48: Natural gas | C48: 1.369 | D48: DKK/m3 | G48: =IFERROR(C48*(1/C21)*$C$5*$C$7,"-") -> 17.365385 | H48: €/MWhf | K48: Heat | L48: Heat | M48: Electricity
B49: Wood chips | C49: 0 | D49: DKK/ton | G49: =IFERROR(C49*(1/C22)*$C$5*$C$7,"-") -> 0 | H49: €/MWhf | J49: ETS | K49: 1 | L49: 1 | M49: 0
...

Sheet DE-TaxRates
B2: ENERGY AND ELECTRICITY TAX
B4: Fuel | C4: Tax rate | D4: Unit | E4: Note | G4: Tax rate | H4: Unit
B5: Biogas | C5: 0 | D5: €/MWhf | G5: 0 | H5: €/MWhf
B6: Electricity | C6: 20.5 | D6: €/MWhf | G6: =C6 -> 20.5 | H6: €/MWhf | J6: CHP exemption | K6: 0
B7: Industrial heat | G7: 0 | H7: €/MWhf
B8: Gas oil | C8: 61.35 | D8: €/m3 | E8: - Full exemption for CHPs assumed | G8: =C8*(1/'DK-TaxRates'!C19)*'DK-TaxRates'!C5 -> 6.1520891 | H8: €/MWhf
B9: Municipal waste | G9: 0 | H9: €/MWhf
B10: Natural gas | C10: 5.5 | D10: €/MWhf | E10: - Full exemption for CHPs assumed | G10: =C10 -> 5.5 | H10: €/MWhf
B11: Wood chips | C11: 0 | D11: €/MWhf | G11: =C11 -> 0 | H11: €/MWhf
B12: Wood pellets | C12: 0 | D12: €/MWhf | G12: =C12 -> 0 | H12: €/MWhf
B15: BEHG
B17: Fuel | C17: Tax rate | D17: Unit | E17: Note
B18: Biogas | C18: 55 | D18: €/tCO2 | E18: - Biogenic, zero emission factor
B19: Electricity
B20: Industrial heat
B21: Gas oil | C21: 55 | D21: €/tCO2
B22: Municipal waste | C22: 55 | D22: €/tCO2 | E22: - Fossil fraction only
B23: Natural gas | C23: 55 | D23: €/tCO2
B24: Wood chips | C24: 55 | D24: €/tCO2 | E24: - Biogenic, zero emission factor
B25: Wood pellets | C25: 55 | D25: €/tCO2 | E25: - Biogenic, zero emission factor
B26: *Only applies for non-ETS plants. Waste incinerators apply as well; they are in ETS but in monitoring state
B29: SUMMARY
B31: GENERATOR | C31: TYPE | D31: ETS | E31: FUEL | F31: FUEL | G31: HEAT | H31: ELECTRICITY | I31: EMISSIONS | J31: ETS
B32: AMV1 | C32: BP | D32: TRUE | E32: 'wood pellets' | F32: =$G$12*$K$6 -> 0 | J32: ='EU-ETS'!$C$15/1000 -> 0.07343
B33: AMV4 | C33: BP | D33: TRUE | E33: 'wood chips' | F33: =$G$11*$K$6 -> 0 | J33: ='EU-ETS'!$C$15/1000 -> 0.07343
B34: ARC | C34: BP | D34: TRUE | E34: 'municipal waste' | F34: =$G$9*$K$6 -> 0 | I34: =$C$22/1000 -> 0.055
B35: ARGO5 | C35: BP | D35: TRUE | E35: 'municipal waste' | F35: =$G$9*$K$6 -> 0 | I35: =$C$22/1000 -> 0.055
B36: ARGO6 | C36: BP | D36: TRUE | E36: 'municipal waste' | F36: =$G$9*$K$6 -> 0 | I36: =$C$22/1000 -> 0.055
B37: AVV1 | C37: EX | D37: TRUE | E37: 'wood pellets' | F37: =$G$12*$K$6 -> 0 | J37: ='EU-ETS'!$C$15/1000 -> 0.07343
B38: AVV2 | C38: EX | D38: TRUE | E38: 'wood pellets' | F38: =$G$12*$K$6 -> 0 | J38: ='EU-ETS'!$C$15/1000 -> 0.07343
B39: HCV7 | C39: BP | D39: TRUE | E39: 'natural gas' | F39: =$G$10*$K$6 -> 0 | J39: ='EU-ETS'!$C$15/1000 -> 0.07343
B40: HCV8 | C40: BP | D40: TRUE | E40: 'natural gas' | F40: =$G$10*$K$6 -> 0 | J40: ='EU-ETS'!$C$15/1000 -> 0.07343
B41: KKV8 | C41: BP | D41: TRUE | E41: 'wood chips' | F41: =$G$11*$K$6 -> 0 | J41: ='EU-ETS'!$C$15/1000 -> 0.07343
B42: VF5 | C42: BP | D42: TRUE | E42: 'municipal waste' | F42: =$G$9*$K$6 -> 0 | I42: =$C$22/1000 -> 0.055
B43: VF6 | C43: BP | D43: TRUE | E43: 'municipal waste' | F43: =$G$9*$K$6 -> 0 | I43: =$C$22/1000 -> 0.055
B44: HOB_BG-S | C44: HO | D44: FALSE | E44: 'biogas' | F44: =$G$5 -> 0 | I44: =$C$18/1000 -> 0.055
B45: HOB_EL | C45: HO | D45: FALSE | E45: 'electricity' | F45: =$G$6 -> 20.5
B46: HOB_GO-L | C46: HO | D46: TRUE | E46: 'gas oil' | F46: =$G$8 -> 6.1520891 | J46: ='EU-ETS'!$C$15/1000 -> 0.07343
B47: HOB_GO-S | C47: HO | D47: FALSE | E47: 'gas oil' | F47: =$G$8 -> 6.1520891 | I47: =$C$21/1000 -> 0.055
B48: HOB_NG-L | C48: HO | D48: TRUE | E48: 'natural gas' | F48: =$G$10 -> 5.5 | J48: ='EU-ETS'!$C$15/1000 -> 0.07343
...

Sheet FR-TaxRates
B2: Month (2025) | C2: Electricity | D2: Natural Gas non-ETS | E2: Natural Gas ETS | F2: Gas oil
B3: January | C3: 20.5 | D3: 17.16 | E3: 1.52 | F3: 15.62
B4: February | C4: 0.5 | D4: 17.16 | E4: 1.52 | F4: 15.62
B5: March | C5: 0.5 | D5: 17.16 | E5: 1.52 | F5: 15.62
B6: April | C6: 0.5 | D6: 17.16 | E6: 1.52 | F6: 15.62
B7: May | C7: 0.5 | D7: 17.16 | E7: 1.52 | F7: 15.62
B8: June | C8: 0.5 | D8: 17.16 | E8: 1.52 | F8: 15.62
B9: July | C9: 0.5 | D9: 17.16 | E9: 1.52 | F9: 15.62
B10: August | C10: 0.5 | D10: 15.43 | E10: 1.52 | F10: 15.43
B11: September | C11: 0.5 | D11: 15.43 | E11: 1.52 | F11: 15.43
B12: October | C12: 0.5 | D12: 15.43 | E12: 1.52 | F12: 15.43
B13: November | C13: 0.5 | D13: 15.43 | E13: 1.52 | F13: 15.43
B14: December | C14: 0.5 | D14: 15.43 | E14: 1.52 | F14: 15.43
B15: Mean | C15: =AVERAGE(C3:C14) -> 2.1666667 | D15: =AVERAGE(D3:D14) -> 16.439167 | E15: =AVERAGE(E3:E14) -> 1.52 | F15: =AVERAGE(F3:F14) -> 15.540833
B18: Fuel | C18: Tax rate | D18: Unit | E18: Note
B19: Biogas | C19: 0 | D19: €/MWhf | E19: - Assumed unblended with natural gas, therefore exempt
B20: Electricity | C20: =C15 -> 2.1666667 | D20: €/MWhf | E20: - Annual mean for electro-intensive industries
B21: Industrial heat
B22: Gas oil | C22: =F15 -> 15.540833 | D22: €/MWhf | E22: - Annual mean
B23: Municipal waste | C23: 15 | D23: €/MWhf | E23: - High energy-recovery installation assumed
B24: Natural gas (ETS) | C24: =E15 -> 1.52 | D24: €/MWhf
B25: Natural gas (non-ETS) | C25: =D15 -> 16.439167 | D25: €/MWhf
B26: Wood chips
B27: Wood pellets
B31: SUMMARY
B33: GENERATOR | C33: TYPE | D33: ETS | E33: FUEL | F33: FUEL | G33: HEAT | H33: ELECTRICITY | I33: EMISSIONS | J33: ETS
B34: AMV1 | C34: BP | D34: TRUE | E34: 'wood pellets' | F34: =$C$27 -> 0 | J34: ='EU-ETS'!$C$15/1000 -> 0.07343
B35: AMV4 | C35: BP | D35: TRUE | E35: 'wood chips' | F35: =$C$26 -> 0 | J35: ='EU-ETS'!$C$15/1000 -> 0.07343
B36: ARC | C36: BP | D36: TRUE | E36: 'municipal waste' | F36: =$C$23 -> 15
B37: ARGO5 | C37: BP | D37: TRUE | E37: 'municipal waste' | F37: =$C$23 -> 15
B38: ARGO6 | C38: BP | D38: TRUE | E38: 'municipal waste' | F38: =$C$23 -> 15
B39: AVV1 | C39: EX | D39: TRUE | E39: 'wood pellets' | F39: =$C$27 -> 0 | J39: ='EU-ETS'!$C$15/1000 -> 0.07343
B40: AVV2 | C40: EX | D40: TRUE | E40: 'wood pellets' | F40: =$C$27 -> 0 | J40: ='EU-ETS'!$C$15/1000 -> 0.07343
B41: HCV7 | C41: BP | D41: TRUE | E41: 'natural gas' | F41: =$C$24 -> 1.52 | J41: ='EU-ETS'!$C$15/1000 -> 0.07343
B42: HCV8 | C42: BP | D42: TRUE | E42: 'natural gas' | F42: =$C$24 -> 1.52 | J42: ='EU-ETS'!$C$15/1000 -> 0.07343
B43: KKV8 | C43: BP | D43: TRUE | E43: 'wood chips' | F43: =$C$26 -> 0 | J43: ='EU-ETS'!$C$15/1000 -> 0.07343
B44: VF5 | C44: BP | D44: TRUE | E44: 'municipal waste' | F44: =$C$23 -> 15
B45: VF6 | C45: BP | D45: TRUE | E45: 'municipal waste' | F45: =$C$23 -> 15
B46: HOB_BG-S | C46: HO | D46: FALSE | E46: 'biogas' | F46: =$C$19 -> 0
B47: HOB_EL | C47: HO | D47: FALSE | E47: 'electricity' | F47: =$C$20 -> 2.1666667
...

Sheet EU-ETS
B3: Fuel | C3: DK | E3: FR | G3: DE
C4: HO | D4: CHP | E4: HO | F4: CHP | G4: HO | H4: CHP
B5: Biogas | C5: ✓(0) | D5: ✓(0) | E5: ✓(0) | F5: ✓(0) | G5: ✓(0) | H5: ✓(0)
B6: Electricity | C6: ✗ | D6: ✗ | E6: ✗ | F6: ✗ | G6: ✗ | H6: ✗
B7: Industrial heat | C7: ✗ | D7: ✗ | E7: ✗ | F7: ✗ | G7: ✗ | H7: ✗
B8: Gas oil | C8: ✓ | D8: ✓ | E8: ✓ | F8: ✓ | G8: ✓ | H8: ✓
B9: Municipal waste | C9: ✓ | D9: ✓ | E9: ✗ | F9: ✗ | G9: ✓/✗ | H9: ✓/✗
B10: Natural gas | C10: ✓ | D10: ✓ | E10: ✓ | F10: ✓ | G10: ✓ | H10: ✓
B11: Wood chips | C11: ✓(0) | D11: ✓(0) | E11: ✓(0) | F11: ✓(0) | G11: ✓(0) | H11: ✓(0)
B12: Wood pellets | C12: ✓(0) | D12: ✓(0) | E12: ✓(0) | F12: ✓(0) | G12: ✓(0) | H12: ✓(0)
B15: EU ETS price | C15: =73.43 -> 73.43 | D15: €/ton-CO2
